Workbook

Sheet RESUMO
A1: RESUMO EXECUTIVO — DRE Box Ceasa Recife/PE — 1º Semestre 2026 — Igarashi HF
A2: Todos os valores por fórmula, ligados às abas de detalhe. Fonte: "RESULTADO 1S2026 Box RecifePE" (DRE Gerencial, relatório interno).
A4: CONSOLIDADO — MÊS A MÊS
A5: LINHA | B5: JANEIRO/26 | C5: FEVEREIRO/26 | D5: MARÇO/26 | E5: ABRIL/26 | F5: MAIO/26 | G5: JUNHO/26 | H5: ACUMULADO 1S26 | I5: % Receita
A6: RECEITA LÍQUIDA | B6: =CONSOLIDADO!B4 -> 4216602.6 | C6: =CONSOLIDADO!C4 -> 4053441.7 | D6: =CONSOLIDADO!D4 -> 6886368.3 | E6: =CONSOLIDADO!E4 -> 5695913.3 | F6: =CONSOLIDADO!F4 -> 9746787.4 | G6: =CONSOLIDADO!G4 -> 9673245.5 | H6: =CONSOLIDADO!H4 -> 40272359 | I6: =IF(H$6=0,0,H6/H$6) -> 1
A7: (-) CMV | B7: =CONSOLIDADO!B14 -> 3965797.7 | C7: =CONSOLIDADO!C14 -> 3653568.3 | D7: =CONSOLIDADO!D14 -> 7198070.3 | E7: =CONSOLIDADO!E14 -> 5340582.1 | F7: =CONSOLIDADO!F14 -> 9321557.8 | G7: =CONSOLIDADO!G14 -> 9633137.5 | H7: =CONSOLIDADO!H14 -> 39112714 | I7: =IF(H$6=0,0,H7/H$6) -> 0.97120494
A8: (=) LUCRO BRUTO | B8: =CONSOLIDADO!B25 -> 250804.91 | C8: =CONSOLIDADO!C25 -> 399873.46 | D8: =CONSOLIDADO!D25 -> -311702.04 | E8: =CONSOLIDADO!E25 -> 355331.15 | F8: =CONSOLIDADO!F25 -> 425229.6 | G8: =CONSOLIDADO!G25 -> 40107.92 | H8: =CONSOLIDADO!H25 -> 1159645 | I8: =IF(H$6=0,0,H8/H$6) -> 0.02879506
A9: (-) DESPESAS OPERACIONAIS | B9: =CONSOLIDADO!B26 -> 288864.08 | C9: =CONSOLIDADO!C26 -> 311047.24 | D9: =CONSOLIDADO!D26 -> 399775.68 | E9: =CONSOLIDADO!E26 -> 414246.74 | F9: =CONSOLIDADO!F26 -> 381310.28 | G9: =CONSOLIDADO!G26 -> 447740.47 | H9: =CONSOLIDADO!H26 -> 2242984.5 | I9: =IF(H$6=0,0,H9/H$6) -> 0.055695384
A10: (=) RESULTADO OPERACIONAL | B10: =CONSOLIDADO!B53 -> -38059.17 | C10: =CONSOLIDADO!C53 -> 88826.21 | D10: =CONSOLIDADO!D53 -> -711477.72 | E10: =CONSOLIDADO!E53 -> -58915.59 | F10: =CONSOLIDADO!F53 -> 43919.31 | G10: =CONSOLIDADO!G53 -> -407632.55 | H10: =CONSOLIDADO!H53 -> -1083339.5 | I10: =IF(H$6=0,0,H10/H$6) -> -0.026900324
A11: (+/-) RESULTADO FINANCEIRO | B11: =CONSOLIDADO!B54 -> -2047.11 | C11: =CONSOLIDADO!C54 -> 19292.8 | D11: =CONSOLIDADO!D54 -> 15787.02 | E11: =CONSOLIDADO!E54 -> 25962.15 | F11: =CONSOLIDADO!F54 -> -33546.78 | G11: =CONSOLIDADO!G54 -> -98604.31 | H11: =CONSOLIDADO!H54 -> -73156.23 | I11: =IF(H$6=0,0,H11/H$6) -> -0.001816537
A12: (=) RESULTADO LÍQUIDO | B12: =CONSOLIDADO!B62 -> -40106.28 | C12: =CONSOLIDADO!C62 -> 108119.01 | D12: =CONSOLIDADO!D62 -> -695690.7 | E12: =CONSOLIDADO!E62 -> -32953.44 | F12: =CONSOLIDADO!F62 -> 10372.53 | G12: =CONSOLIDADO!G62 -> -506236.86 | H12: =CONSOLIDADO!H62 -> -1156495.7 | I12: =IF(H$6=0,0,H12/H$6) -> -0.028716861
A14: ACUMULADO 1S26 — POR PRODUTO (fórmulas ligadas às abas)
A15: PRODUTO | B15: RECEITA LÍQUIDA | C15: CMV | D15: LUCRO BRUTO | E15: DESPESAS OPER. | F15: RES. OPERACIONAL | G15: RES. FINANCEIRO | H15: RESULTADO LÍQUIDO | I15: MARGEM LÍQ. %
A16: BATATA | B16: =BATATA!H4 -> 31766429 | C16: =BATATA!H7 -> 30168530 | D16: =BATATA!H11 -> 1597899.7 | E16: =BATATA!H12 -> 1752893 | F16: =BATATA!H39 -> -154993.29 | G16: =BATATA!H40 -> -63181.25 | H16: =BATATA!H48 -> -218174.56 | I16: =IF(B16=0,0,H16/B16) -> -0.0068680857
A17: CEBOLA | B17: =CEBOLA!H4 -> 4912302.5 | C17: =CEBOLA!H7 -> 5408175.3 | D17: =CEBOLA!H11 -> -495872.9 | E17: =CEBOLA!H12 -> 282072.97 | F17: =CEBOLA!H39 -> -777945.88 | G17: =CEBOLA!H40 -> -9913.36 | H17: =CEBOLA!H48 -> -787859.24 | I17: =IF(B17=0,0,H17/B17) -> -0.16038492
A18: CENOURA | B18: =CENOURA!H4 -> 2340573.9 | C18: =CENOURA!H7 -> 2340081.1 | D18: =CENOURA!H11 -> 492.75 | E18: =CENOURA!H12 -> 134593.98 | F18: =CENOURA!H39 -> -134101.21 | G18: =CENOURA!H40 -> -81.11 | H18: =CENOURA!H48 -> -134182.32 | I18: =IF(B18=0,0,H18/B18) -> -0.057328813
A19: REPOLHO | B19: =REPOLHO!H4 -> 518856.76 | C19: =REPOLHO!H7 -> 572859.91 | D19: =REPOLHO!H11 -> -54003.15 | E19: =REPOLHO!H12 -> 32362.08 | F19: =REPOLHO!H39 -> -86365.23 | G19: =REPOLHO!H40 -> 219.8 | H19: =REPOLHO!H48 -> -86145.44 | I19: =IF(B19=0,0,H19/B19) -> -0.16602933
A20: ALHO | B20: =ALHO!H4 -> 424275 | C20: =ALHO!H7 -> 362979.12 | D20: =ALHO!H11 -> 61295.88 | E20: =ALHO!H12 -> 24118.07 | F20: =ALHO!H39 -> 37177.81 | G20: =ALHO!H40 -> 63.35 | H20: =ALHO!H48 -> 37241.15 | I20: =IF(B20=0,0,H20/B20) -> 0.087775971
A21: MAÇÃ | B21: =MAÇÃ!H4 -> 219900 | C21: =MAÇÃ!H7 -> 171316.68 | D21: =MAÇÃ!H10 -> 48583.32 | E21: =MAÇÃ!H11 -> 11778.32 | F21: =MAÇÃ!H38 -> 36805 | G21: =MAÇÃ!H39 -> -88.48 | H21: =MAÇÃ!H47 -> 36716.53 | I21: =IF(B21=0,0,H21/B21) -> 0.16696921
A22: BETERRABA | B22: =BETERRABA!H4 -> 69112.38 | C22: =BETERRABA!H7 -> 71821.45 | D22: =BETERRABA!H11 -> -2709.07 | E22: =BETERRABA!H12 -> 3840.82 | F22: =BETERRABA!H39 -> -6549.9 | G22: =BETERRABA!H40 -> -198.17 | H22: =BETERRABA!H48 -> -6748.08 | I22: =IF(B22=0,0,H22/B22) -> -0.097639236
A23: MIRTILO | B23: =MIRTILO!H4 -> 20909 | C23: =MIRTILO!H7 -> 16950.52 | D23: =MIRTILO!H11 -> 3958.48 | E23: =MIRTILO!H12 -> 1325.24 | F23: =MIRTILO!H39 -> 2633.24 | G23: =MIRTILO!H40 -> 22.99 | H23: =MIRTILO!H48 -> 2656.21 | I23: =IF(B23=0,0,H23/B23) -> 0.12703668
A24: TOTAL (soma produtos) | B24: =SUM(B16:B23) -> 40272359 | C24: =SUM(C16:C23) -> 39112714 | D24: =SUM(D16:D23) -> 1159645 | E24: =SUM(E16:E23) -> 2242984.5 | F24: =SUM(F16:F23) -> -1083339.5 | G24: =SUM(G16:G23) -> -73156.23 | H24: =SUM(H16:H23) -> -1156495.8 | I24: =IF(B24=0,0,H24/B24) -> -0.028716862
A25: Conferência: a linha TOTAL deve bater com a aba CONSOLIDADO (diferenças de centavos = arredondamento da fonte).

Sheet CONSOLIDADO
A1: DRE GERENCIAL — CONSOLIDADO — Box Ceasa Recife/PE — 1º Semestre 2026
A2: Fonte: "RESULTADO 1S2026 Box RecifePE" (DRE Gerencial, relatório interno Igarashi HF). ACUMULADO e % por fórmula — diferenças de até R$ 0,02 vs. o relatório-fonte são arredondamento dos meses na fonte.
A3: LINHA | B3: JANEIRO/26 | C3: FEVEREIRO/26 | D3: MARÇO/26 | E3: ABRIL/26 | F3: MAIO/26 | G3: JUNHO/26 | H3: ACUMULADO 1S26
A4: RECEITA LÍQUIDA | B4: 4216602.6 | C4: 4053441.7 | D4: 6886368.3 | E4: 5695913.3 | F4: 9746787.4 | G4: 9673245.5 | H4: =SUM(B4:G4) -> 40272359
A5: BATATA | B5: 3242617.5 | C5: 3127824 | D5: 5562027 | E5: 4343678.1 | F5: 7960686.5 | G5: 8015027.5 | H5: =SUM(B5:G5) -> 32251861
A6: CEBOLA | B6: 719585 | C6: 512193.08 | D6: 570059 | E6: 1051126 | F6: 956351.5 | G6: 1813352.6 | H6: =SUM(B6:G6) -> 5622667.2
A7: CENOURA | B7: 180778 | C7: 407448 | D7: 720184 | E7: 247150 | F7: 580672 | G7: 268517 | H7: =SUM(B7:G7) -> 2404749
A8: ALHO | B8: 77495 | C8: 60345 | D8: 75875 | E8: 45685 | F8: 164735 | G8: 140 | H8: =SUM(B8:G8) -> 424275
A9: REPOLHO | B9: 133831.84 | C9: 177040 | D9: 189007 | E9: 0 | F9: 53065 | G9: 71172 | H9: =SUM(B9:G9) -> 624115.84
A10: BETERRABA | B10: 28274 | C10: 180 | D10: 0 | E10: 5970 | F10: 21464 | G10: 14599 | H10: =SUM(B10:G10) -> 70487
A11: MIRTILO | B11: 9504 | C11: 0 | D11: 10253 | E11: 1008 | F11: 144 | G11: 0 | H11: =SUM(B11:G11) -> 20909
A12: MAÇÃ | B12: 0 | C12: 0 | D12: 0 | E12: 92286 | F12: 117262 | G12: 10352 | H12: =SUM(B12:G12) -> 219900
A13: (-) Devoluções de Vendas | B13: -175482.73 | C13: -231588.34 | D13: -241036.71 | E13: -90989.85 | F13: -107592.59 | G13: -519914.64 | H13: =SUM(B13:G13) -> -1366604.9
A14: (-) CMV | B14: 3965797.7 | C14: 3653568.3 | D14: 7198070.3 | E14: 5340582.1 | F14: 9321557.8 | G14: 9633137.5 | H14: =SUM(B14:G14) -> 39112714
A15: (-) CMV BATATA | B15: 2900361.8 | C15: 2861817.6 | D15: 5728623.3 | E15: 4170263 | F15: 7455180.1 | G15: 7594807.6 | H15: =SUM(B15:G15) -> 30711053
... A62: (=) RESULTADO LÍQUIDO | B62: -40106.28 | C62: 108119.01 | D62: -695690.7 | E62: -32953.44 | F62: 10372.53 | G62: -506236.86 | H62: =SUM(B62:G62) -> -1156495.7
A64: ANÁLISE VERTICAL — % da Receita Líquida (fórmulas)
A65: LINHA | B65: JANEIRO/26 | C65: FEVEREIRO/26 | D65: MARÇO/26 | E65: ABRIL/26 | F65: MAIO/26 | G65: JUNHO/26 | H65: ACUMULADO 1S26
A66: RECEITA LÍQUIDA | B66: =IF(B$4=0,0,B4/B$4) -> 1 | C66: =IF(C$4=0,0,C4/C$4) -> 1 | D66: =IF(D$4=0,0,D4/D$4) -> 1 | E66: =IF(E$4=0,0,E4/E$4) -> 1 | F66: =IF(F$4=0,0,F4/F$4) -> 1 | G66: =IF(G$4=0,0,G4/G$4) -> 1 | H66: =IF(H$4=0,0,H4/H$4) -> 1
A67: BATATA | B67: =IF(B$4=0,0,B5/B$4) -> 0.76901188 | C67: =IF(C$4=0,0,C5/C$4) -> 0.77164647 | D67: =IF(D$4=0,0,D5/D$4) -> 0.80768654 | E67: =IF(E$4=0,0,E5/E$4) -> 0.76259555 | F67: =IF(F$4=0,0,F5/F$4) -> 0.81674978 | G67: =IF(G$4=0,0,G5/G$4) -> 0.82857688 | H67: =IF(H$4=0,0,H5/H$4) -> 0.8008436
A68: CEBOLA | B68: =IF(B$4=0,0,B6/B$4) -> 0.17065516 | C68: =IF(C$4=0,0,C6/C$4) -> 0.12636004 | D68: =IF(D$4=0,0,D6/D$4) -> 0.082780789 | E68: =IF(E$4=0,0,E6/E$4) -> 0.18454038 | F68: =IF(F$4=0,0,F6/F$4) -> 0.098119663 | G68: =IF(G$4=0,0,G6/G$4) -> 0.18746062 | H68: =IF(H$4=0,0,H6/H$4) -> 0.13961604
A69: CENOURA | B69: =IF(B$4=0,0,B7/B$4) -> 0.042872904 | C69: =IF(C$4=0,0,C7/C$4) -> 0.10051902 | D69: =IF(D$4=0,0,D7/D$4) -> 0.1045811 | E69: =IF(E$4=0,0,E7/E$4) -> 0.043390759 | F69: =IF(F$4=0,0,F7/F$4) -> 0.059575733 | G69: =IF(G$4=0,0,G7/G$4) -> 0.027758729 | H69: =IF(H$4=0,0,H7/H$4) -> 0.059712147
A70: ALHO | B70: =IF(B$4=0,0,B8/B$4) -> 0.01837854 | C70: =IF(C$4=0,0,C8/C$4) -> 0.014887349 | D70: =IF(D$4=0,0,D8/D$4) -> 0.011018144 | E70: =IF(E$4=0,0,E8/E$4) -> 0.0080206629 | F70: =IF(F$4=0,0,F8/F$4) -> 0.016901466 | G70: =IF(G$4=0,0,G8/G$4) -> 1.4472909e-05 | H70: =IF(H$4=0,0,H8/H$4) -> 0.010535142
A71: REPOLHO | B71: =IF(B$4=0,0,B9/B$4) -> 0.031739258 | C71: =IF(C$4=0,0,C9/C$4) -> 0.043676463 | D71: =IF(D$4=0,0,D9/D$4) -> 0.027446543 | E71: =IF(E$4=0,0,E9/E$4) -> 0 | F71: =IF(F$4=0,0,F9/F$4) -> 0.005444358 | G71: =IF(G$4=0,0,G9/G$4) -> 0.0073576134 | H71: =IF(H$4=0,0,H9/H$4) -> 0.015497375
A72: BETERRABA | B72: =IF(B$4=0,0,B10/B$4) -> 0.0067053983 | C72: =IF(C$4=0,0,C10/C$4) -> 4.4406707e-05 | D72: =IF(D$4=0,0,D10/D$4) -> 0 | E72: =IF(E$4=0,0,E10/E$4) -> 0.0010481199 | F72: =IF(F$4=0,0,F10/F$4) -> 0.0022021615 | G72: =IF(G$4=0,0,G10/G$4) -> 0.0015092143 | H72: =IF(H$4=0,0,H10/H$4) -> 0.0017502575
A73: MIRTILO | B73: =IF(B$4=0,0,B11/B$4) -> 0.0022539473 | C73: =IF(C$4=0,0,C11/C$4) -> 0 | D73: =IF(D$4=0,0,D11/D$4) -> 0.0014888835 | E73: =IF(E$4=0,0,E11/E$4) -> 0.00017696899 | F73: =IF(F$4=0,0,F11/F$4) -> 1.4774099e-05 | G73: =IF(G$4=0,0,G11/G$4) -> 0 | H73: =IF(H$4=0,0,H11/H$4) -> 0.00051918985
A74: MAÇÃ | B74: =IF(B$4=0,0,B12/B$4) -> 0 | C74: =IF(C$4=0,0,C12/C$4) -> 0 | D74: =IF(D$4=0,0,D12/D$4) -> 0 | E74: =IF(E$4=0,0,E12/E$4) -> 0.016202143 | F74: =IF(F$4=0,0,F12/F$4) -> 0.012030836 | G74: =IF(G$4=0,0,G12/G$4) -> 0.0010701682 | H74: =IF(H$4=0,0,H12/H$4) -> 0.0054603208
A75: (-) Devoluções de Vendas | B75: =IF(B$4=0,0,B13/B$4) -> -0.04161709 | C75: =IF(C$4=0,0,C13/C$4) -> -0.057133753 | D75: =IF(D$4=0,0,D13/D$4) -> -0.035002007 | E75: =IF(E$4=0,0,E13/E$4) -> -0.015974585 | F75: =IF(F$4=0,0,F13/F$4) -> -0.011038775 | G75: =IF(G$4=0,0,G13/G$4) -> -0.053747694 | H75: =IF(H$4=0,0,H13/H$4) -> -0.033934065
A76: (-) CMV | B76: =IF(B$4=0,0,B14/B$4) -> 0.94051967 | C76: =IF(C$4=0,0,C14/C$4) -> 0.90134965 | D76: =IF(D$4=0,0,D14/D$4) -> 1.0452636 | E76: =IF(E$4=0,0,E14/E$4) -> 0.93761647 | F76: =IF(F$4=0,0,F14/F$4) -> 0.95637233 | G76: =IF(G$4=0,0,G14/G$4) -> 0.99585373 | H76: =IF(H$4=0,0,H14/H$4) -> 0.97120494
A77: (-) CMV BATATA | B77: =IF(B$4=0,0,B15/B$4) -> 0.68784329 | C77: =IF(C$4=0,0,C15/C$4) -> 0.70602163 | D77: =IF(D$4=0,0,D15/D$4) -> 0.83187873 | E77: =IF(E$4=0,0,E15/E$4) -> 0.73215002 | F77: =IF(F$4=0,0,F15/F$4) -> 0.76488588 | G77: =IF(G$4=0,0,G15/G$4) -> 0.78513542 | H77: =IF(H$4=0,0,H15/H$4) -> 0.76258392
... A124: (=) RESULTADO LÍQUIDO | B124: =IF(B$4=0,0,B62/B$4) -> -0.0095115152 | C124: =IF(C$4=0,0,C62/C$4) -> 0.026673384 | D124: =IF(D$4=0,0,D62/D$4) -> -0.10102432 | E124: =IF(E$4=0,0,E62/E$4) -> -0.0057854533 | F124: =IF(F$4=0,0,F62/F$4) -> 0.0010641999 | G124: =IF(G$4=0,0,G62/G$4) -> -0.052333714 | H124: =IF(H$4=0,0,H62/H$4) -> -0.028716861

Sheet BATATA
A1: DRE GERENCIAL — BATATA — Box Ceasa Recife/PE — 1º Semestre 2026
A2: Fonte: "RESULTADO 1S2026 Box RecifePE" (DRE Gerencial, relatório interno Igarashi HF). ACUMULADO e % por fórmula — diferenças de até R$ 0,02 vs. o relatório-fonte são arredondamento dos meses na fonte.
A3: LINHA | B3: JANEIRO/26 | C3: FEVEREIRO/26 | D3: MARÇO/26 | E3: ABRIL/26 | F3: MAIO/26 | G3: JUNHO/26 | H3: ACUMULADO 1S26
A4: RECEITA LÍQUIDA | B4: 3158603 | C4: 2955216.7 | D4: 5477838.1 | E4: 4334825.3 | F4: 7914315.5 | G4: 7925630.7 | H4: =SUM(B4:G4) -> 31766429
A5: BATATA | B5: 3242617.5 | C5: 3127824 | D5: 5562027 | E5: 4343678.1 | F5: 7960686.5 | G5: 8015027.5 | H5: =SUM(B5:G5) -> 32251861
A6: (-) Devoluções de Vendas | B6: -84014.45 | C6: -172607.34 | D6: -84188.91 | E6: -8852.85 | F6: -46370.97 | G6: -89396.77 | H6: =SUM(B6:G6) -> -485431.29
A7: (-) CMV | B7: 2864361.8 | C7: 2584803.8 | D7: 5709723.3 | E7: 3985613 | F7: 7429220.1 | G7: 7594807.6 | H7: =SUM(B7:G7) -> 30168530
A8: (-) CMV BATATA | B8: 2900361.8 | C8: 2861817.6 | D8: 5728623.3 | E8: 4170263 | F8: 7455180.1 | G8: 7594807.6 | H8: =SUM(B8:G8) -> 30711053
A9: (-) Perdas de Mercadorias | B9: 0 | C9: 0 | D9: 0 | E9: 0 | F9: 0 | G9: 0 | H9: =SUM(B9:G9) -> 0
A10: Devoluções/Descontos Compras | B10: -36000 | C10: -277013.75 | D10: -18900 | E10: -184650 | F10: -25960 | G10: 0 | H10: =SUM(B10:G10) -> -542523.75
A11: (=) LUCRO BRUTO | B11: 294241.24 | C11: 370412.85 | D11: -231885.19 | E11: 349212.28 | F11: 485095.43 | G11: 330823.09 | H11: =SUM(B11:G11) -> 1597899.7
A12: (-) DESPESAS OPERACIONAIS | B12: 216384.38 | C12: 226773.21 | D12: 318006 | E12: 315258.88 | F12: 309620.98 | G12: 366849.54 | H12: =SUM(B12:G12) -> 1752893
A13: Folha de Pagamento (Bruto) | B13: 30997.14 | C13: 74244.67 | D13: 98274.64 | E13: 107916.27 | F13: 139326.94 | G13: 147890.2 | H13: =SUM(B13:G13) -> 598649.86
A14: NF Rivera Consultoria (Rodney) | B14: 28766.27 | C14: 0 | D14: 0 | E14: 0 | F14: 0 | G14: 0 | H14: =SUM(B14:G14) -> 28766.27
A15: Vale Transporte e Vale Alimentação | B15: 1806.19 | C15: 1725.04 | D15: 1761.99 | E15: 2079.69 | F15: 3832.18 | G15: 4145.76 | H15: =SUM(B15:G15) -> 15350.85
... A48: (=) RESULTADO LÍQUIDO | B48: 76323.39 | C48: 157705.32 | D48: -537333.23 | E48: 53711.67 | F48: 148234.72 | G48: -116816.43 | H48: =SUM(B48:G48) -> -218174.56
A50: ANÁLISE VERTICAL — % da Receita Líquida (fórmulas)
A51: LINHA | B51: JANEIRO/26 | C51: FEVEREIRO/26 | D51: MARÇO/26 | E51: ABRIL/26 | F51: MAIO/26 | G51: JUNHO/26 | H51: ACUMULADO 1S26
A52: RECEITA LÍQUIDA | B52: =IF(B$4=0,0,B4/B$4) -> 1 | C52: =IF(C$4=0,0,C4/C$4) -> 1 | D52: =IF(D$4=0,0,D4/D$4) -> 1 | E52: =IF(E$4=0,0,E4/E$4) -> 1 | F52: =IF(F$4=0,0,F4/F$4) -> 1 | G52: =IF(G$4=0,0,G4/G$4) -> 1 | H52: =IF(H$4=0,0,H4/H$4) -> 1
A53: BATATA | B53: =IF(B$4=0,0,B5/B$4) -> 1.0265986 | C53: =IF(C$4=0,0,C5/C$4) -> 1.0584077 | D53: =IF(D$4=0,0,D5/D$4) -> 1.015369 | E53: =IF(E$4=0,0,E5/E$4) -> 1.0020423 | F53: =IF(F$4=0,0,F5/F$4) -> 1.0058591 | G53: =IF(G$4=0,0,G5/G$4) -> 1.0112795 | H53: =IF(H$4=0,0,H5/H$4) -> 1.0152813
A54: (-) Devoluções de Vendas | B54: =IF(B$4=0,0,B6/B$4) -> -0.02659861 | C54: =IF(C$4=0,0,C6/C$4) -> -0.058407677 | D54: =IF(D$4=0,0,D6/D$4) -> -0.015369003 | E54: =IF(E$4=0,0,E6/E$4) -> -0.0020422622 | F54: =IF(F$4=0,0,F6/F$4) -> -0.0058591258 | G54: =IF(G$4=0,0,G6/G$4) -> -0.011279452 | H54: =IF(H$4=0,0,H6/H$4) -> -0.015281267
A55: (-) CMV | B55: =IF(B$4=0,0,B7/B$4) -> 0.9068445 | C55: =IF(C$4=0,0,C7/C$4) -> 0.87465797 | D55: =IF(D$4=0,0,D7/D$4) -> 1.0423315 | E55: =IF(E$4=0,0,E7/E$4) -> 0.91944029 | F55: =IF(F$4=0,0,F7/F$4) -> 0.93870658 | G55: =IF(G$4=0,0,G7/G$4) -> 0.95825908 | H55: =IF(H$4=0,0,H7/H$4) -> 0.94969848
A56: (-) CMV BATATA | B56: =IF(B$4=0,0,B8/B$4) -> 0.91824195 | C56: =IF(C$4=0,0,C8/C$4) -> 0.96839518 | D56: =IF(D$4=0,0,D8/D$4) -> 1.0457818 | E56: =IF(E$4=0,0,E8/E$4) -> 0.96203716 | F56: =IF(F$4=0,0,F8/F$4) -> 0.94198672 | G56: =IF(G$4=0,0,G8/G$4) -> 0.95825908 | H56: =IF(H$4=0,0,H8/H$4) -> 0.966777
A57: (-) Perdas de Mercadorias | B57: =IF(B$4=0,0,B9/B$4) -> 0 | C57: =IF(C$4=0,0,C9/C$4) -> 0 | D57: =IF(D$4=0,0,D9/D$4) -> 0 | E57: =IF(E$4=0,0,E9/E$4) -> 0 | F57: =IF(F$4=0,0,F9/F$4) -> 0 | G57: =IF(G$4=0,0,G9/G$4) -> 0 | H57: =IF(H$4=0,0,H9/H$4) -> 0
A58: Devoluções/Descontos Compras | B58: =IF(B$4=0,0,B10/B$4) -> -0.011397444 | C58: =IF(C$4=0,0,C10/C$4) -> -0.093737205 | D58: =IF(D$4=0,0,D10/D$4) -> -0.0034502663 | E58: =IF(E$4=0,0,E10/E$4) -> -0.042596873 | F58: =IF(F$4=0,0,F10/F$4) -> -0.003280132 | G58: =IF(G$4=0,0,G10/G$4) -> 0 | H58: =IF(H$4=0,0,H10/H$4) -> -0.017078525
A59: (=) LUCRO BRUTO | B59: =IF(B$4=0,0,B11/B$4) -> 0.093155498 | C59: =IF(C$4=0,0,C11/C$4) -> 0.12534203 | D59: =IF(D$4=0,0,D11/D$4) -> -0.042331516 | E59: =IF(E$4=0,0,E11/E$4) -> 0.080559713 | F59: =IF(F$4=0,0,F11/F$4) -> 0.061293415 | G59: =IF(G$4=0,0,G11/G$4) -> 0.041740916 | H59: =IF(H$4=0,0,H11/H$4) -> 0.050301521
A60: (-) DESPESAS OPERACIONAIS | B60: =IF(B$4=0,0,B12/B$4) -> 0.068506354 | C60: =IF(C$4=0,0,C12/C$4) -> 0.076736577 | D60: =IF(D$4=0,0,D12/D$4) -> 0.058053194 | E60: =IF(E$4=0,0,E12/E$4) -> 0.07272701 | F60: =IF(F$4=0,0,F12/F$4) -> 0.039121637 | G60: =IF(G$4=0,0,G12/G$4) -> 0.046286479 | H60: =IF(H$4=0,0,H12/H$4) -> 0.055180674
A61: Folha de Pagamento (Bruto) | B61: =IF(B$4=0,0,B13/B$4) -> 0.0098135598 | C61: =IF(C$4=0,0,C13/C$4) -> 0.025123258 | D61: =IF(D$4=0,0,D13/D$4) -> 0.017940406 | E61: =IF(E$4=0,0,E13/E$4) -> 0.024895183 | F61: =IF(F$4=0,0,F13/F$4) -> 0.017604421 | G61: =IF(G$4=0,0,G13/G$4) -> 0.018659739 | H61: =IF(H$4=0,0,H13/H$4) -> 0.018845362
A62: NF Rivera Consultoria (Rodney) | B62: =IF(B$4=0,0,B14/B$4) -> 0.0091072761 | C62: =IF(C$4=0,0,C14/C$4) -> 0 | D62: =IF(D$4=0,0,D14/D$4) -> 0 | E62: =IF(E$4=0,0,E14/E$4) -> 0 | F62: =IF(F$4=0,0,F14/F$4) -> 0 | G62: =IF(G$4=0,0,G14/G$4) -> 0 | H62: =IF(H$4=0,0,H14/H$4) -> 0.00090555566
A63: Vale Transporte e Vale Alimentação | B63: =IF(B$4=0,0,B15/B$4) -> 0.00057183191 | C63: =IF(C$4=0,0,C15/C$4) -> 0.00058372708 | D63: =IF(D$4=0,0,D15/D$4) -> 0.00032165792 | E63: =IF(E$4=0,0,E15/E$4) -> 0.00047976328 | F63: =IF(F$4=0,0,F15/F$4) -> 0.00048420865 | G63: =IF(G$4=0,0,G15/G$4) -> 0.00052308266 | H63: =IF(H$4=0,0,H15/H$4) -> 0.00048324128
... A96: (=) RESULTADO LÍQUIDO | B96: =IF(B$4=0,0,B48/B$4) -> 0.024163654 | C96: =IF(C$4=0,0,C48/C$4) -> 0.053365062 | D96: =IF(D$4=0,0,D48/D$4) -> -0.098092207 | E96: =IF(E$4=0,0,E48/E$4) -> 0.012390735 | F96: =IF(F$4=0,0,F48/F$4) -> 0.018729948 | G96: =IF(G$4=0,0,G48/G$4) -> -0.01473907 | H96: =IF(H$4=0,0,H48/H$4) -> -0.0068680857

Sheet CEBOLA
A1: DRE GERENCIAL — CEBOLA — Box Ceasa Recife/PE — 1º Semestre 2026
A2: Fonte: "RESULTADO 1S2026 Box RecifePE" (DRE Gerencial, relatório interno Igarashi HF). ACUMULADO e % por fórmula — diferenças de até R$ 0,02 vs. o relatório-fonte são arredondamento dos meses na fonte.
A3: LINHA | B3: JANEIRO/26 | C3: FEVEREIRO/26 | D3: MARÇO/26 | E3: ABRIL/26 | F3: MAIO/26 | G3: JUNHO/26 | H3: ACUMULADO 1S26
A4: RECEITA LÍQUIDA | B4: 686121 | C4: 467743.08 | D4: 459588 | E4: 993974 | F4: 904081.58 | G4: 1400794.8 | H4: =SUM(B4:G4) -> 4912302.5
A5: CEBOLA | B5: 719585 | C5: 512193.08 | D5: 570059 | E5: 1051126 | F5: 956351.5 | G5: 1813352.6 | H5: =SUM(B5:G5) -> 5622667.2
A6: (-) Devoluções de Vendas | B6: -33464 | C6: -44450 | D6: -110471 | E6: -57152 | F6: -52269.92 | G6: -412557.81 | H6: =SUM(B6:G6) -> -710364.73
A7: (-) CMV | B7: 657296.59 | C7: 526926.43 | D7: 556425.71 | E7: 999228.91 | F7: 906552.47 | G7: 1761745.2 | H7: =SUM(B7:G7) -> 5408175.3
A8: (-) CMV CEBOLA | B8: 657296.59 | C8: 526926.43 | D8: 556425.71 | E8: 1000028.9 | F8: 910952.47 | G8: 1768745.2 | H8: =SUM(B8:G8) -> 5420375.3
A9: (-) Perdas de Mercadorias | B9: 0 | C9: 0 | D9: 0 | E9: 0 | F9: 0 | G9: 0 | H9: =SUM(B9:G9) -> 0
A10: Devoluções/Descontos Compras | B10: 0 | C10: 0 | D10: 0 | E10: -800 | F10: -4400 | G10: -7000 | H10: =SUM(B10:G10) -> -12200
A11: (=) LUCRO BRUTO | B11: 28824.41 | C11: -59183.35 | D11: -96837.71 | E11: -5254.91 | F11: -2470.89 | G11: -360950.45 | H11: =SUM(B11:G11) -> -495872.9
A12: (-) DESPESAS OPERACIONAIS | B12: 47003.65 | C12: 35893 | D12: 26680.55 | E12: 72288.76 | F12: 35369.15 | G12: 64837.86 | H12: =SUM(B12:G12) -> 282072.97
A13: Folha de Pagamento (Bruto) | B13: 6733.29 | C13: 11751.23 | D13: 8245.2 | E13: 24745.16 | F13: 15915.83 | G13: 26138.47 | H13: =SUM(B13:G13) -> 93529.18
A14: NF Rivera Consultoria (Rodney) | B14: 6248.69 | C14: 0 | D14: 0 | E14: 0 | F14: 0 | G14: 0 | H14: =SUM(B14:G14) -> 6248.69
A15: Vale Transporte e Vale Alimentação | B15: 392.35 | C15: 273.03 | D15: 147.83 | E15: 476.87 | F15: 437.76 | G15: 732.73 | H15: =SUM(B15:G15) -> 2460.57
... A48: (=) RESULTADO LÍQUIDO | B48: -18512.35 | C48: -92850.07 | D48: -122464.65 | E48: -73013.11 | F48: -40951.74 | G48: -440067.32 | H48: =SUM(B48:G48) -> -787859.24
A50: ANÁLISE VERTICAL — % da Receita Líquida (fórmulas)
A51: LINHA | B51: JANEIRO/26 | C51: FEVEREIRO/26 | D51: MARÇO/26 | E51: ABRIL/26 | F51: MAIO/26 | G51: JUNHO/26 | H51: ACUMULADO 1S26
A52: RECEITA LÍQUIDA | B52: =IF(B$4=0,0,B4/B$4) -> 1 | C52: =IF(C$4=0,0,C4/C$4) -> 1 | D52: =IF(D$4=0,0,D4/D$4) -> 1 | E52: =IF(E$4=0,0,E4/E$4) -> 1 | F52: =IF(F$4=0,0,F4/F$4) -> 1 | G52: =IF(G$4=0,0,G4/G$4) -> 1 | H52: =IF(H$4=0,0,H4/H$4) -> 1
A53: CEBOLA | B53: =IF(B$4=0,0,B5/B$4) -> 1.0487727 | C53: =IF(C$4=0,0,C5/C$4) -> 1.0950308 | D53: =IF(D$4=0,0,D5/D$4) -> 1.2403696 | E53: =IF(E$4=0,0,E5/E$4) -> 1.0574985 | F53: =IF(F$4=0,0,F5/F$4) -> 1.0578155 | G53: =IF(G$4=0,0,G5/G$4) -> 1.294517 | H53: =IF(H$4=0,0,H5/H$4) -> 1.1446093
A54: (-) Devoluções de Vendas | B54: =IF(B$4=0,0,B6/B$4) -> -0.048772738 | C54: =IF(C$4=0,0,C6/C$4) -> -0.095030802 | D54: =IF(D$4=0,0,D6/D$4) -> -0.24036964 | E54: =IF(E$4=0,0,E6/E$4) -> -0.057498486 | F54: =IF(F$4=0,0,F6/F$4) -> -0.057815491 | G54: =IF(G$4=0,0,G6/G$4) -> -0.29451695 | H54: =IF(H$4=0,0,H6/H$4) -> -0.14460932
A55: (-) CMV | B55: =IF(B$4=0,0,B7/B$4) -> 0.95798932 | C55: =IF(C$4=0,0,C7/C$4) -> 1.1265296 | D55: =IF(D$4=0,0,D7/D$4) -> 1.2107055 | E55: =IF(E$4=0,0,E7/E$4) -> 1.0052868 | F55: =IF(F$4=0,0,F7/F$4) -> 1.002733 | G55: =IF(G$4=0,0,G7/G$4) -> 1.2576755 | H55: =IF(H$4=0,0,H7/H$4) -> 1.1009451
A56: (-) CMV CEBOLA | B56: =IF(B$4=0,0,B8/B$4) -> 0.95798932 | C56: =IF(C$4=0,0,C8/C$4) -> 1.1265296 | D56: =IF(D$4=0,0,D8/D$4) -> 1.2107055 | E56: =IF(E$4=0,0,E8/E$4) -> 1.0060916 | F56: =IF(F$4=0,0,F8/F$4) -> 1.0075999 | G56: =IF(G$4=0,0,G8/G$4) -> 1.2626726 | H56: =IF(H$4=0,0,H8/H$4) -> 1.1034287
A57: (-) Perdas de Mercadorias | B57: =IF(B$4=0,0,B9/B$4) -> 0 | C57: =IF(C$4=0,0,C9/C$4) -> 0 | D57: =IF(D$4=0,0,D9/D$4) -> 0 | E57: =IF(E$4=0,0,E9/E$4) -> 0 | F57: =IF(F$4=0,0,F9/F$4) -> 0 | G57: =IF(G$4=0,0,G9/G$4) -> 0 | H57: =IF(H$4=0,0,H9/H$4) -> 0
A58: Devoluções/Descontos Compras | B58: =IF(B$4=0,0,B10/B$4) -> 0 | C58: =IF(C$4=0,0,C10/C$4) -> 0 | D58: =IF(D$4=0,0,D10/D$4) -> 0 | E58: =IF(E$4=0,0,E10/E$4) -> -0.00080485003 | F58: =IF(F$4=0,0,F10/F$4) -> -0.0048668174 | G58: =IF(G$4=0,0,G10/G$4) -> -0.0049971631 | H58: =IF(H$4=0,0,H10/H$4) -> -0.0024835604
A59: (=) LUCRO BRUTO | B59: =IF(B$4=0,0,B11/B$4) -> 0.04201068 | C59: =IF(C$4=0,0,C11/C$4) -> -0.12652961 | D59: =IF(D$4=0,0,D11/D$4) -> -0.21070548 | E59: =IF(E$4=0,0,E11/E$4) -> -0.0052867681 | F59: =IF(F$4=0,0,F11/F$4) -> -0.0027330388 | G59: =IF(G$4=0,0,G11/G$4) -> -0.25767547 | H59: =IF(H$4=0,0,H11/H$4) -> -0.10094511
A60: (-) DESPESAS OPERACIONAIS | B60: =IF(B$4=0,0,B12/B$4) -> 0.068506357 | C60: =IF(C$4=0,0,C12/C$4) -> 0.076736571 | D60: =IF(D$4=0,0,D12/D$4) -> 0.058053191 | E60: =IF(E$4=0,0,E12/E$4) -> 0.072727013 | F60: =IF(F$4=0,0,F12/F$4) -> 0.039121635 | G60: =IF(G$4=0,0,G12/G$4) -> 0.04628648 | H60: =IF(H$4=0,0,H12/H$4) -> 0.057421743
A61: Folha de Pagamento (Bruto) | B61: =IF(B$4=0,0,B13/B$4) -> 0.0098135606 | C61: =IF(C$4=0,0,C13/C$4) -> 0.025123258 | D61: =IF(D$4=0,0,D13/D$4) -> 0.017940416 | E61: =IF(E$4=0,0,E13/E$4) -> 0.024895178 | F61: =IF(F$4=0,0,F13/F$4) -> 0.017604418 | G61: =IF(G$4=0,0,G13/G$4) -> 0.018659742 | H61: =IF(H$4=0,0,H13/H$4) -> 0.019039784
A62: NF Rivera Consultoria (Rodney) | B62: =IF(B$4=0,0,B14/B$4) -> 0.0091072712 | C62: =IF(C$4=0,0,C14/C$4) -> 0 | D62: =IF(D$4=0,0,D14/D$4) -> 0 | E62: =IF(E$4=0,0,E14/E$4) -> 0 | F62: =IF(F$4=0,0,F14/F$4) -> 0 | G62: =IF(G$4=0,0,G14/G$4) -> 0 | H62: =IF(H$4=0,0,H14/H$4) -> 0.0012720491
A63: Vale Transporte e Vale Alimentação | B63: =IF(B$4=0,0,B15/B$4) -> 0.00057183791 | C63: =IF(C$4=0,0,C15/C$4) -> 0.00058371788 | D63: =IF(D$4=0,0,D15/D$4) -> 0.00032165766 | E63: =IF(E$4=0,0,E15/E$4) -> 0.00047976104 | F63: =IF(F$4=0,0,F15/F$4) -> 0.00048420409 | G63: =IF(G$4=0,0,G15/G$4) -> 0.00052308161 | H63: =IF(H$4=0,0,H15/H$4) -> 0.00050089953
... A96: (=) RESULTADO LÍQUIDO | B96: =IF(B$4=0,0,B48/B$4) -> -0.026981174 | C96: =IF(C$4=0,0,C48/C$4) -> -0.19850656 | D96: =IF(D$4=0,0,D48/D$4) -> -0.26646616 | E96: =IF(E$4=0,0,E48/E$4) -> -0.073455754 | F96: =IF(F$4=0,0,F48/F$4) -> -0.04529651 | G96: =IF(G$4=0,0,G48/G$4) -> -0.31415545 | H96: =IF(H$4=0,0,H48/H$4) -> -0.16038492

Sheet CENOURA
A1: DRE GERENCIAL — CENOURA — Box Ceasa Recife/PE — 1º Semestre 2026
A2: Fonte: "RESULTADO 1S2026 Box RecifePE" (DRE Gerencial, relatório interno Igarashi HF). ACUMULADO e % por fórmula — diferenças de até R$ 0,02 vs. o relatório-fonte são arredondamento dos meses na fonte.
A3: LINHA | B3: JANEIRO/26 | C3: FEVEREIRO/26 | D3: MARÇO/26 | E3: ABRIL/26 | F3: MAIO/26 | G3: JUNHO/26 | H3: ACUMULADO 1S26
A4: RECEITA LÍQUIDA | B4: 180646 | C4: 393927 | D4: 720184 | E4: 222165 | F4: 572287.86 | G4: 251364 | H4: =SUM(B4:G4) -> 2340573.9
A5: CENOURA | B5: 180778 | C5: 407448 | D5: 720184 | E5: 247150 | F5: 580672 | G5: 268517 | H5: =SUM(B5:G5) -> 2404749
A6: (-) Devoluções de Vendas | B6: -132 | C6: -13521 | D6: 0 | E6: -24985 | F6: -8384.14 | G6: -17153 | H6: =SUM(B6:G6) -> -64175.14
A7: (-) CMV | B7: 177209.42 | C7: 380834.49 | D7: 695594.98 | E7: 241411.48 | F7: 650678.52 | G7: 194352.22 | H7: =SUM(B7:G7) -> 2340081.1
A8: (-) CMV CENOURA | B8: 177209.42 | C8: 380834.49 | D8: 695594.98 | E8: 241411.48 | F8: 650678.52 | G8: 194352.22 | H8: =SUM(B8:G8) -> 2340081.1
A9: (-) Perdas de Mercadorias | B9: 0 | C9: 0 | D9: 0 | E9: 0 | F9: 0 | G9: 0 | H9: =SUM(B9:G9) -> 0
A10: Devoluções/Descontos Compras | B10: 0 | C10: 0 | D10: 0 | E10: 0 | F10: 0 | G10: 0 | H10: =SUM(B10:G10) -> 0
A11: (=) LUCRO BRUTO | B11: 3436.58 | C11: 13092.51 | D11: 24589.02 | E11: -19246.48 | F11: -78390.66 | G11: 57011.78 | H11: =SUM(B11:G11) -> 492.75
A12: (-) DESPESAS OPERACIONAIS | B12: 12375.4 | C12: 30228.61 | D12: 41808.98 | E12: 16157.4 | F12: 22388.84 | G12: 11634.75 | H12: =SUM(B12:G12) -> 134593.98
A13: Folha de Pagamento (Bruto) | B13: 1772.78 | C13: 9896.73 | D13: 12920.39 | E13: 5530.84 | F13: 10074.8 | G13: 4690.39 | H13: =SUM(B13:G13) -> 44885.93
A14: NF Rivera Consultoria (Rodney) | B14: 1645.19 | C14: 0 | D14: 0 | E14: 0 | F14: 0 | G14: 0 | H14: =SUM(B14:G14) -> 1645.19
A15: Vale Transporte e Vale Alimentação | B15: 103.3 | C15: 229.95 | D15: 231.65 | E15: 106.59 | F15: 277.11 | G15: 131.48 | H15: =SUM(B15:G15) -> 1080.08
... A48: (=) RESULTADO LÍQUIDO | B48: -9026.53 | C48: -15261.16 | D48: -15568.93 | E48: -34391.24 | F48: -102749.21 | G48: 42814.75 | H48: =SUM(B48:G48) -> -134182.32
A50: ANÁLISE VERTICAL — % da Receita Líquida (fórmulas)
A51: LINHA | B51: JANEIRO/26 | C51: FEVEREIRO/26 | D51: MARÇO/26 | E51: ABRIL/26 | F51: MAIO/26 | G51: JUNHO/26 | H51: ACUMULADO 1S26
A52: RECEITA LÍQUIDA | B52: =IF(B$4=0,0,B4/B$4) -> 1 | C52: =IF(C$4=0,0,C4/C$4) -> 1 | D52: =IF(D$4=0,0,D4/D$4) -> 1 | E52: =IF(E$4=0,0,E4/E$4) -> 1 | F52: =IF(F$4=0,0,F4/F$4) -> 1 | G52: =IF(G$4=0,0,G4/G$4) -> 1 | H52: =IF(H$4=0,0,H4/H$4) -> 1
A53: CENOURA | B53: =IF(B$4=0,0,B5/B$4) -> 1.0007307 | C53: =IF(C$4=0,0,C5/C$4) -> 1.0343236 | D53: =IF(D$4=0,0,D5/D$4) -> 1 | E53: =IF(E$4=0,0,E5/E$4) -> 1.1124615 | F53: =IF(F$4=0,0,F5/F$4) -> 1.0146502 | G53: =IF(G$4=0,0,G5/G$4) -> 1.0682397 | H53: =IF(H$4=0,0,H5/H$4) -> 1.0274185
A54: (-) Devoluções de Vendas | B54: =IF(B$4=0,0,B6/B$4) -> -0.00073071089 | C54: =IF(C$4=0,0,C6/C$4) -> -0.034323618 | D54: =IF(D$4=0,0,D6/D$4) -> 0 | E54: =IF(E$4=0,0,E6/E$4) -> -0.11246146 | F54: =IF(F$4=0,0,F6/F$4) -> -0.014650215 | G54: =IF(G$4=0,0,G6/G$4) -> -0.068239684 | H54: =IF(H$4=0,0,H6/H$4) -> -0.027418549
A55: (-) CMV | B55: =IF(B$4=0,0,B7/B$4) -> 0.98097616 | C55: =IF(C$4=0,0,C7/C$4) -> 0.96676412 | D55: =IF(D$4=0,0,D7/D$4) -> 0.96585731 | E55: =IF(E$4=0,0,E7/E$4) -> 1.0866315 | F55: =IF(F$4=0,0,F7/F$4) -> 1.1369777 | G55: =IF(G$4=0,0,G7/G$4) -> 0.77319035 | H55: =IF(H$4=0,0,H7/H$4) -> 0.99978947
A56: (-) CMV CENOURA | B56: =IF(B$4=0,0,B8/B$4) -> 0.98097616 | C56: =IF(C$4=0,0,C8/C$4) -> 0.96676412 | D56: =IF(D$4=0,0,D8/D$4) -> 0.96585731 | E56: =IF(E$4=0,0,E8/E$4) -> 1.0866315 | F56: =IF(F$4=0,0,F8/F$4) -> 1.1369777 | G56: =IF(G$4=0,0,G8/G$4) -> 0.77319035 | H56: =IF(H$4=0,0,H8/H$4) -> 0.99978947
A57: (-) Perdas de Mercadorias | B57: =IF(B$4=0,0,B9/B$4) -> 0 | C57: =IF(C$4=0,0,C9/C$4) -> 0 | D57: =IF(D$4=0,0,D9/D$4) -> 0 | E57: =IF(E$4=0,0,E9/E$4) -> 0 | F57: =IF(F$4=0,0,F9/F$4) -> 0 | G57: =IF(G$4=0,0,G9/G$4) -> 0 | H57: =IF(H$4=0,0,H9/H$4) -> 0
A58: Devoluções/Descontos Compras | B58: =IF(B$4=0,0,B10/B$4) -> 0 | C58: =IF(C$4=0,0,C10/C$4) -> 0 | D58: =IF(D$4=0,0,D10/D$4) -> 0 | E58: =IF(E$4=0,0,E10/E$4) -> 0 | F58: =IF(F$4=0,0,F10/F$4) -> 0 | G58: =IF(G$4=0,0,G10/G$4) -> 0 | H58: =IF(H$4=0,0,H10/H$4) -> 0
A59: (=) LUCRO BRUTO | B59: =IF(B$4=0,0,B11/B$4) -> 0.019023837 | C59: =IF(C$4=0,0,C11/C$4) -> 0.033235879 | D59: =IF(D$4=0,0,D11/D$4) -> 0.034142691 | E59: =IF(E$4=0,0,E11/E$4) -> -0.086631468 | F59: =IF(F$4=0,0,F11/F$4) -> -0.13697767 | G59: =IF(G$4=0,0,G11/G$4) -> 0.22680965 | H59: =IF(H$4=0,0,H11/H$4) -> 0.00021052529
A60: (-) DESPESAS OPERACIONAIS | B60: =IF(B$4=0,0,B12/B$4) -> 0.068506361 | C60: =IF(C$4=0,0,C12/C$4) -> 0.076736578 | D60: =IF(D$4=0,0,D12/D$4) -> 0.058053192 | E60: =IF(E$4=0,0,E12/E$4) -> 0.072727027 | F60: =IF(F$4=0,0,F12/F$4) -> 0.039121641 | G60: =IF(G$4=0,0,G12/G$4) -> 0.046286461 | H60: =IF(H$4=0,0,H12/H$4) -> 0.057504692
A61: Folha de Pagamento (Bruto) | B61: =IF(B$4=0,0,B13/B$4) -> 0.009813558 | C61: =IF(C$4=0,0,C13/C$4) -> 0.025123259 | D61: =IF(D$4=0,0,D13/D$4) -> 0.017940401 | E61: =IF(E$4=0,0,E13/E$4) -> 0.024895191 | F61: =IF(F$4=0,0,F13/F$4) -> 0.017604427 | G61: =IF(G$4=0,0,G13/G$4) -> 0.018659752 | H61: =IF(H$4=0,0,H13/H$4) -> 0.019177318
A62: NF Rivera Consultoria (Rodney) | B62: =IF(B$4=0,0,B14/B$4) -> 0.0091072595 | C62: =IF(C$4=0,0,C14/C$4) -> 0 | D62: =IF(D$4=0,0,D14/D$4) -> 0 | E62: =IF(E$4=0,0,E14/E$4) -> 0 | F62: =IF(F$4=0,0,F14/F$4) -> 0 | G62: =IF(G$4=0,0,G14/G$4) -> 0 | H62: =IF(H$4=0,0,H14/H$4) -> 0.00070290027
A63: Vale Transporte e Vale Alimentação | B63: =IF(B$4=0,0,B15/B$4) -> 0.00057183663 | C63: =IF(C$4=0,0,C15/C$4) -> 0.0005837376 | D63: =IF(D$4=0,0,D15/D$4) -> 0.00032165391 | E63: =IF(E$4=0,0,E15/E$4) -> 0.00047977854 | F63: =IF(F$4=0,0,F15/F$4) -> 0.00048421436 | G63: =IF(G$4=0,0,G15/G$4) -> 0.00052306615 | H63: =IF(H$4=0,0,H15/H$4) -> 0.00046145948
... A96: (=) RESULTADO LÍQUIDO | B96: =IF(B$4=0,0,B48/B$4) -> -0.049968059 | C96: =IF(C$4=0,0,C48/C$4) -> -0.038741087 | D96: =IF(D$4=0,0,D48/D$4) -> -0.021617989 | E96: =IF(E$4=0,0,E48/E$4) -> -0.15480044 | F96: =IF(F$4=0,0,F48/F$4) -> -0.17954113 | G96: =IF(G$4=0,0,G48/G$4) -> 0.17032968 | H96: =IF(H$4=0,0,H48/H$4) -> -0.057328813

Sheet REPOLHO
A1: DRE GERENCIAL — REPOLHO — Box Ceasa Recife/PE — 1º Semestre 2026
A2: Fonte: "RESULTADO 1S2026 Box RecifePE" (DRE Gerencial, relatório interno Igarashi HF). ACUMULADO e % por fórmula — diferenças de até R$ 0,02 vs. o relatório-fonte são arredondamento dos meses na fonte.
A3: LINHA | B3: JANEIRO/26 | C3: FEVEREIRO/26 | D3: MARÇO/26 | E3: ABRIL/26 | F3: MAIO/26 | G3: JUNHO/26 | H3: ACUMULADO 1S26
A4: RECEITA LÍQUIDA | B4: 75959.56 | C4: 176030 | D4: 142630.2 | E4: 0 | F4: 53065 | G4: 71172 | H4: =SUM(B4:G4) -> 518856.76
A5: REPOLHO | B5: 133831.84 | C5: 177040 | D5: 189007 | E5: 0 | F5: 53065 | G5: 71172 | H5: =SUM(B5:G5) -> 624115.84
A6: (-) Devoluções de Vendas | B6: -57872.28 | C6: -1010 | D6: -46376.8 | E6: 0 | F6: 0 | G6: 0 | H6: =SUM(B6:G6) -> -105259.08
A7: (-) CMV | B7: 167052.97 | C7: 111257.29 | D7: 165278.66 | E7: 0 | F7: 66771.37 | G7: 62499.62 | H7: =SUM(B7:G7) -> 572859.91
A8: (-) CMV REPOLHO | B8: 167052.97 | C8: 138532.29 | D8: 165278.66 | E8: 0 | F8: 48879.69 | G8: 62499.62 | H8: =SUM(B8:G8) -> 582243.23
A9: (-) Perdas de Mercadorias | B9: 0 | C9: 0 | D9: 0 | E9: 0 | F9: 17891.67 | G9: 0 | H9: =SUM(B9:G9) -> 17891.67
A10: Devoluções/Descontos Compras | B10: 0 | C10: -27275 | D10: 0 | E10: 0 | F10: 0 | G10: 0 | H10: =SUM(B10:G10) -> -27275
A11: (=) LUCRO BRUTO | B11: -91093.41 | C11: 64772.71 | D11: -22648.46 | E11: 0 | F11: -13706.37 | G11: 8672.38 | H11: =SUM(B11:G11) -> -54003.15
A12: (-) DESPESAS OPERACIONAIS | B12: 5203.71 | C12: 13507.94 | D12: 8280.14 | E12: 0 | F12: 2075.99 | G12: 3294.3 | H12: =SUM(B12:G12) -> 32362.08
A13: Folha de Pagamento (Bruto) | B13: 745.43 | C13: 4422.45 | D13: 2558.84 | E13: 0 | F13: 934.18 | G13: 1328.05 | H13: =SUM(B13:G13) -> 9988.95
A14: NF Rivera Consultoria (Rodney) | B14: 691.78 | C14: 0 | D14: 0 | E14: 0 | F14: 0 | G14: 0 | H14: =SUM(B14:G14) -> 691.78
A15: Vale Transporte e Vale Alimentação | B15: 43.44 | C15: 102.75 | D15: 45.88 | E15: 0 | F15: 25.69 | G15: 37.23 | H15: =SUM(B15:G15) -> 254.99
... A48: (=) RESULTADO LÍQUIDO | B48: -96334 | C48: 52102.6 | D48: -30601.62 | E48: 0 | F48: -15965 | G48: 4652.58 | H48: =SUM(B48:G48) -> -86145.44
A50: ANÁLISE VERTICAL — % da Receita Líquida (fórmulas)
A51: LINHA | B51: JANEIRO/26 | C51: FEVEREIRO/26 | D51: MARÇO/26 | E51: ABRIL/26 | F51: MAIO/26 | G51: JUNHO/26 | H51: ACUMULADO 1S26
A52: RECEITA LÍQUIDA | B52: =IF(B$4=0,0,B4/B$4) -> 1 | C52: =IF(C$4=0,0,C4/C$4) -> 1 | D52: =IF(D$4=0,0,D4/D$4) -> 1 | E52: =IF(E$4=0,0,E4/E$4) -> 0 | F52: =IF(F$4=0,0,F4/F$4) -> 1 | G52: =IF(G$4=0,0,G4/G$4) -> 1 | H52: =IF(H$4=0,0,H4/H$4) -> 1
A53: REPOLHO | B53: =IF(B$4=0,0,B5/B$4) -> 1.7618828 | C53: =IF(C$4=0,0,C5/C$4) -> 1.0057377 | D53: =IF(D$4=0,0,D5/D$4) -> 1.3251541 | E53: =IF(E$4=0,0,E5/E$4) -> 0 | F53: =IF(F$4=0,0,F5/F$4) -> 1 | G53: =IF(G$4=0,0,G5/G$4) -> 1 | H53: =IF(H$4=0,0,H5/H$4) -> 1.2028673
A54: (-) Devoluções de Vendas | B54: =IF(B$4=0,0,B6/B$4) -> -0.76188277 | C54: =IF(C$4=0,0,C6/C$4) -> -0.0057376584 | D54: =IF(D$4=0,0,D6/D$4) -> -0.32515414 | E54: =IF(E$4=0,0,E6/E$4) -> 0 | F54: =IF(F$4=0,0,F6/F$4) -> 0 | G54: =IF(G$4=0,0,G6/G$4) -> 0 | H54: =IF(H$4=0,0,H6/H$4) -> -0.20286732
A55: (-) CMV | B55: =IF(B$4=0,0,B7/B$4) -> 2.1992356 | C55: =IF(C$4=0,0,C7/C$4) -> 0.63203596 | D55: =IF(D$4=0,0,D7/D$4) -> 1.1587915 | E55: =IF(E$4=0,0,E7/E$4) -> 0 | F55: =IF(F$4=0,0,F7/F$4) -> 1.258294 | G55: =IF(G$4=0,0,G7/G$4) -> 0.87814899 | H55: =IF(H$4=0,0,H7/H$4) -> 1.104081
A56: (-) CMV REPOLHO | B56: =IF(B$4=0,0,B8/B$4) -> 2.1992356 | C56: =IF(C$4=0,0,C8/C$4) -> 0.78698114 | D56: =IF(D$4=0,0,D8/D$4) -> 1.1587915 | E56: =IF(E$4=0,0,E8/E$4) -> 0 | F56: =IF(F$4=0,0,F8/F$4) -> 0.92112862 | G56: =IF(G$4=0,0,G8/G$4) -> 0.87814899 | H56: =IF(H$4=0,0,H8/H$4) -> 1.1221656
A57: (-) Perdas de Mercadorias | B57: =IF(B$4=0,0,B9/B$4) -> 0 | C57: =IF(C$4=0,0,C9/C$4) -> 0 | D57: =IF(D$4=0,0,D9/D$4) -> 0 | E57: =IF(E$4=0,0,E9/E$4) -> 0 | F57: =IF(F$4=0,0,F9/F$4) -> 0.33716517 | G57: =IF(G$4=0,0,G9/G$4) -> 0 | H57: =IF(H$4=0,0,H9/H$4) -> 0.03448287
A58: Devoluções/Descontos Compras | B58: =IF(B$4=0,0,B10/B$4) -> 0 | C58: =IF(C$4=0,0,C10/C$4) -> -0.15494518 | D58: =IF(D$4=0,0,D10/D$4) -> 0 | E58: =IF(E$4=0,0,E10/E$4) -> 0 | F58: =IF(F$4=0,0,F10/F$4) -> 0 | G58: =IF(G$4=0,0,G10/G$4) -> 0 | H58: =IF(H$4=0,0,H10/H$4) -> -0.052567495
A59: (=) LUCRO BRUTO | B59: =IF(B$4=0,0,B11/B$4) -> -1.1992356 | C59: =IF(C$4=0,0,C11/C$4) -> 0.36796404 | D59: =IF(D$4=0,0,D11/D$4) -> -0.15879148 | E59: =IF(E$4=0,0,E11/E$4) -> 0 | F59: =IF(F$4=0,0,F11/F$4) -> -0.25829398 | G59: =IF(G$4=0,0,G11/G$4) -> 0.12185101 | H59: =IF(H$4=0,0,H11/H$4) -> -0.10408104
A60: (-) DESPESAS OPERACIONAIS | B60: =IF(B$4=0,0,B12/B$4) -> 0.068506321 | C60: =IF(C$4=0,0,C12/C$4) -> 0.076736579 | D60: =IF(D$4=0,0,D12/D$4) -> 0.058053203 | E60: =IF(E$4=0,0,E12/E$4) -> 0 | F60: =IF(F$4=0,0,F12/F$4) -> 0.039121643 | G60: =IF(G$4=0,0,G12/G$4) -> 0.046286461 | H60: =IF(H$4=0,0,H12/H$4) -> 0.062371896
A61: Folha de Pagamento (Bruto) | B61: =IF(B$4=0,0,B13/B$4) -> 0.0098135113 | C61: =IF(C$4=0,0,C13/C$4) -> 0.025123274 | D61: =IF(D$4=0,0,D13/D$4) -> 0.01794038 | E61: =IF(E$4=0,0,E13/E$4) -> 0 | F61: =IF(F$4=0,0,F13/F$4) -> 0.017604447 | G61: =IF(G$4=0,0,G13/G$4) -> 0.018659726 | H61: =IF(H$4=0,0,H13/H$4) -> 0.019251845
A62: NF Rivera Consultoria (Rodney) | B62: =IF(B$4=0,0,B14/B$4) -> 0.0091072144 | C62: =IF(C$4=0,0,C14/C$4) -> 0 | D62: =IF(D$4=0,0,D14/D$4) -> 0 | E62: =IF(E$4=0,0,E14/E$4) -> 0 | F62: =IF(F$4=0,0,F14/F$4) -> 0 | G62: =IF(G$4=0,0,G14/G$4) -> 0 | H62: =IF(H$4=0,0,H14/H$4) -> 0.0013332774
A63: Vale Transporte e Vale Alimentação | B63: =IF(B$4=0,0,B15/B$4) -> 0.00057188325 | C63: =IF(C$4=0,0,C15/C$4) -> 0.00058370732 | D63: =IF(D$4=0,0,D15/D$4) -> 0.00032167101 | E63: =IF(E$4=0,0,E15/E$4) -> 0 | F63: =IF(F$4=0,0,F15/F$4) -> 0.00048412325 | G63: =IF(G$4=0,0,G15/G$4) -> 0.00052309897 | H63: =IF(H$4=0,0,H15/H$4) -> 0.00049144585
... A96: (=) RESULTADO LÍQUIDO | B96: =IF(B$4=0,0,B48/B$4) -> -1.2682275 | C96: =IF(C$4=0,0,C48/C$4) -> 0.29598705 | D96: =IF(D$4=0,0,D48/D$4) -> -0.21455218 | E96: =IF(E$4=0,0,E48/E$4) -> 0 | F96: =IF(F$4=0,0,F48/F$4) -> -0.30085744 | G96: =IF(G$4=0,0,G48/G$4) -> 0.065370932 | H96: =IF(H$4=0,0,H48/H$4) -> -0.16602933

Sheet ALHO
A1: DRE GERENCIAL — ALHO — Box Ceasa Recife/PE — 1º Semestre 2026
A2: Fonte: "RESULTADO 1S2026 Box RecifePE" (DRE Gerencial, relatório interno Igarashi HF). ACUMULADO e % por fórmula — diferenças de até R$ 0,02 vs. o relatório-fonte são arredondamento dos meses na fonte.
A3: LINHA | B3: JANEIRO/26 | C3: FEVEREIRO/26 | D3: MARÇO/26 | E3: ABRIL/26 | F3: MAIO/26 | G3: JUNHO/26 | H3: ACUMULADO 1S26
A4: RECEITA LÍQUIDA | B4: 77495 | C4: 60345 | D4: 75875 | E4: 45685 | F4: 164735 | G4: 140 | H4: =SUM(B4:G4) -> 424275
A5: ALHO | B5: 77495 | C5: 60345 | D5: 75875 | E5: 45685 | F5: 164735 | G5: 140 | H5: =SUM(B5:G5) -> 424275
A6: (-) Devoluções de Vendas | B6: 0 | C6: 0 | D6: 0 | E6: 0 | F6: 0 | G6: 0 | H6: =SUM(B6:G6) -> 0
A7: (-) CMV | B7: 62511.4 | C7: 49291.38 | D7: 62924.5 | E7: 34987.65 | F7: 153189.58 | G7: 74.61 | H7: =SUM(B7:G7) -> 362979.12
A8: (-) CMV ALHO | B8: 62511.4 | C8: 49291.38 | D8: 62924.5 | E8: 34987.65 | F8: 153189.58 | G8: 74.61 | H8: =SUM(B8:G8) -> 362979.12
A9: (-) Perdas de Mercadorias | B9: 0 | C9: 0 | D9: 0 | E9: 0 | F9: 0 | G9: 0 | H9: =SUM(B9:G9) -> 0
A10: Devoluções/Descontos Compras | B10: 0 | C10: 0 | D10: 0 | E10: 0 | F10: 0 | G10: 0 | H10: =SUM(B10:G10) -> 0
A11: (=) LUCRO BRUTO | B11: 14983.6 | C11: 11053.62 | D11: 12950.5 | E11: 10697.35 | F11: 11545.42 | G11: 65.39 | H11: =SUM(B11:G11) -> 61295.88
A12: (-) DESPESAS OPERACIONAIS | B12: 5308.9 | C12: 4630.67 | D12: 4404.79 | E12: 3322.53 | F12: 6444.7 | G12: 6.48 | H12: =SUM(B12:G12) -> 24118.07
A13: Folha de Pagamento (Bruto) | B13: 760.5 | C13: 1516.06 | D13: 1361.23 | E13: 1137.34 | F13: 2900.06 | G13: 2.61 | H13: =SUM(B13:G13) -> 7677.8
A14: NF Rivera Consultoria (Rodney) | B14: 705.77 | C14: 0 | D14: 0 | E14: 0 | F14: 0 | G14: 0 | H14: =SUM(B14:G14) -> 705.77
A15: Vale Transporte e Vale Alimentação | B15: 44.31 | C15: 35.22 | D15: 24.41 | E15: 21.92 | F15: 79.77 | G15: 0.07 | H15: =SUM(B15:G15) -> 205.7
... A48: (=) RESULTADO LÍQUIDO | B48: 9637.07 | C48: 6710.17 | D48: 8719.65 | E48: 7583.05 | F48: 4533.73 | G48: 57.48 | H48: =SUM(B48:G48) -> 37241.15
A50: ANÁLISE VERTICAL — % da Receita Líquida (fórmulas)
A51: LINHA | B51: JANEIRO/26 | C51: FEVEREIRO/26 | D51: MARÇO/26 | E51: ABRIL/26 | F51: MAIO/26 | G51: JUNHO/26 | H51: ACUMULADO 1S26
A52: RECEITA LÍQUIDA | B52: =IF(B$4=0,0,B4/B$4) -> 1 | C52: =IF(C$4=0,0,C4/C$4) -> 1 | D52: =IF(D$4=0,0,D4/D$4) -> 1 | E52: =IF(E$4=0,0,E4/E$4) -> 1 | F52: =IF(F$4=0,0,F4/F$4) -> 1 | G52: =IF(G$4=0,0,G4/G$4) -> 1 | H52: =IF(H$4=0,0,H4/H$4) -> 1
A53: ALHO | B53: =IF(B$4=0,0,B5/B$4) -> 1 | C53: =IF(C$4=0,0,C5/C$4) -> 1 | D53: =IF(D$4=0,0,D5/D$4) -> 1 | E53: =IF(E$4=0,0,E5/E$4) -> 1 | F53: =IF(F$4=0,0,F5/F$4) -> 1 | G53: =IF(G$4=0,0,G5/G$4) -> 1 | H53: =IF(H$4=0,0,H5/H$4) -> 1
A54: (-) Devoluções de Vendas | B54: =IF(B$4=0,0,B6/B$4) -> 0 | C54: =IF(C$4=0,0,C6/C$4) -> 0 | D54: =IF(D$4=0,0,D6/D$4) -> 0 | E54: =IF(E$4=0,0,E6/E$4) -> 0 | F54: =IF(F$4=0,0,F6/F$4) -> 0 | G54: =IF(G$4=0,0,G6/G$4) -> 0 | H54: =IF(H$4=0,0,H6/H$4) -> 0
A55: (-) CMV | B55: =IF(B$4=0,0,B7/B$4) -> 0.80665075 | C55: =IF(C$4=0,0,C7/C$4) -> 0.81682625 | D55: =IF(D$4=0,0,D7/D$4) -> 0.82931796 | E55: =IF(E$4=0,0,E7/E$4) -> 0.76584546 | F55: =IF(F$4=0,0,F7/F$4) -> 0.9299152 | G55: =IF(G$4=0,0,G7/G$4) -> 0.53292857 | H55: =IF(H$4=0,0,H7/H$4) -> 0.85552795
A56: (-) CMV ALHO | B56: =IF(B$4=0,0,B8/B$4) -> 0.80665075 | C56: =IF(C$4=0,0,C8/C$4) -> 0.81682625 | D56: =IF(D$4=0,0,D8/D$4) -> 0.82931796 | E56: =IF(E$4=0,0,E8/E$4) -> 0.76584546 | F56: =IF(F$4=0,0,F8/F$4) -> 0.9299152 | G56: =IF(G$4=0,0,G8/G$4) -> 0.53292857 | H56: =IF(H$4=0,0,H8/H$4) -> 0.85552795
A57: (-) Perdas de Mercadorias | B57: =IF(B$4=0,0,B9/B$4) -> 0 | C57: =IF(C$4=0,0,C9/C$4) -> 0 | D57: =IF(D$4=0,0,D9/D$4) -> 0 | E57: =IF(E$4=0,0,E9/E$4) -> 0 | F57: =IF(F$4=0,0,F9/F$4) -> 0 | G57: =IF(G$4=0,0,G9/G$4) -> 0 | H57: =IF(H$4=0,0,H9/H$4) -> 0
A58: Devoluções/Descontos Compras | B58: =IF(B$4=0,0,B10/B$4) -> 0 | C58: =IF(C$4=0,0,C10/C$4) -> 0 | D58: =IF(D$4=0,0,D10/D$4) -> 0 | E58: =IF(E$4=0,0,E10/E$4) -> 0 | F58: =IF(F$4=0,0,F10/F$4) -> 0 | G58: =IF(G$4=0,0,G10/G$4) -> 0 | H58: =IF(H$4=0,0,H10/H$4) -> 0
A59: (=) LUCRO BRUTO | B59: =IF(B$4=0,0,B11/B$4) -> 0.19334925 | C59: =IF(C$4=0,0,C11/C$4) -> 0.18317375 | D59: =IF(D$4=0,0,D11/D$4) -> 0.17068204 | E59: =IF(E$4=0,0,E11/E$4) -> 0.23415454 | F59: =IF(F$4=0,0,F11/F$4) -> 0.070084803 | G59: =IF(G$4=0,0,G11/G$4) -> 0.46707143 | H59: =IF(H$4=0,0,H11/H$4) -> 0.14447205
A60: (-) DESPESAS OPERACIONAIS | B60: =IF(B$4=0,0,B12/B$4) -> 0.068506355 | C60: =IF(C$4=0,0,C12/C$4) -> 0.076736598 | D60: =IF(D$4=0,0,D12/D$4) -> 0.058053245 | E60: =IF(E$4=0,0,E12/E$4) -> 0.072726934 | F60: =IF(F$4=0,0,F12/F$4) -> 0.03912162 | G60: =IF(G$4=0,0,G12/G$4) -> 0.046285714 | H60: =IF(H$4=0,0,H12/H$4) -> 0.056845372
A61: Folha de Pagamento (Bruto) | B61: =IF(B$4=0,0,B13/B$4) -> 0.0098135364 | C61: =IF(C$4=0,0,C13/C$4) -> 0.025123208 | D61: =IF(D$4=0,0,D13/D$4) -> 0.017940428 | E61: =IF(E$4=0,0,E13/E$4) -> 0.024895261 | F61: =IF(F$4=0,0,F13/F$4) -> 0.017604395 | G61: =IF(G$4=0,0,G13/G$4) -> 0.018642857 | H61: =IF(H$4=0,0,H13/H$4) -> 0.018096282
A62: NF Rivera Consultoria (Rodney) | B62: =IF(B$4=0,0,B14/B$4) -> 0.0091072972 | C62: =IF(C$4=0,0,C14/C$4) -> 0 | D62: =IF(D$4=0,0,D14/D$4) -> 0 | E62: =IF(E$4=0,0,E14/E$4) -> 0 | F62: =IF(F$4=0,0,F14/F$4) -> 0 | G62: =IF(G$4=0,0,G14/G$4) -> 0 | H62: =IF(H$4=0,0,H14/H$4) -> 0.001663473
A63: Vale Transporte e Vale Alimentação | B63: =IF(B$4=0,0,B15/B$4) -> 0.00057177882 | C63: =IF(C$4=0,0,C15/C$4) -> 0.00058364405 | D63: =IF(D$4=0,0,D15/D$4) -> 0.00032171334 | E63: =IF(E$4=0,0,E15/E$4) -> 0.00047980738 | F63: =IF(F$4=0,0,F15/F$4) -> 0.00048423225 | G63: =IF(G$4=0,0,G15/G$4) -> 0.0005 | H63: =IF(H$4=0,0,H15/H$4) -> 0.00048482706
... A96: (=) RESULTADO LÍQUIDO | B96: =IF(B$4=0,0,B48/B$4) -> 0.12435731 | C96: =IF(C$4=0,0,C48/C$4) -> 0.11119679 | D96: =IF(D$4=0,0,D48/D$4) -> 0.11492125 | E96: =IF(E$4=0,0,E48/E$4) -> 0.16598555 | F96: =IF(F$4=0,0,F48/F$4) -> 0.027521352 | G96: =IF(G$4=0,0,G48/G$4) -> 0.41057143 | H96: =IF(H$4=0,0,H48/H$4) -> 0.087775971

Sheet MAÇÃ
A1: DRE GERENCIAL — MAÇÃ — Box Ceasa Recife/PE — 1º Semestre 2026
A2: Fonte: "RESULTADO 1S2026 Box RecifePE" (DRE Gerencial, relatório interno Igarashi HF). ACUMULADO e % por fórmula — diferenças de até R$ 0,02 vs. o relatório-fonte são arredondamento dos meses na fonte.
A3: LINHA | B3: JANEIRO/26 | C3: FEVEREIRO/26 | D3: MARÇO/26 | E3: ABRIL/26 | F3: MAIO/26 | G3: JUNHO/26 | H3: ACUMULADO 1S26
A4: RECEITA LÍQUIDA | B4: 0 | C4: 0 | D4: 0 | E4: 92286 | F4: 117262 | G4: 10352 | H4: =SUM(B4:G4) -> 219900
A5: MAÇÃ | B5: 0 | C5: 0 | D5: 0 | E5: 92286 | F5: 117262 | G5: 10352 | H5: =SUM(B5:G5) -> 219900
A6: (-) Devoluções de Vendas | B6: 0 | C6: 0 | D6: 0 | E6: 0 | F6: 0 | G6: 0 | H6: =SUM(B6:G6) -> 0
A7: (-) CMV | B7: 0 | C7: 0 | D7: 0 | E7: 73726.31 | F7: 89664.25 | G7: 7926.12 | H7: =SUM(B7:G7) -> 171316.68
A8: (-) CMV MAÇÃ | B8: 0 | C8: 0 | D8: 0 | E8: 73726.31 | F8: 89664.25 | G8: 7926.12 | H8: =SUM(B8:G8) -> 171316.68
A9: Devoluções/Descontos Compras | B9: 0 | C9: 0 | D9: 0 | E9: 0 | F9: 0 | G9: 0 | H9: =SUM(B9:G9) -> 0
A10: (=) LUCRO BRUTO | B10: 0 | C10: 0 | D10: 0 | E10: 18559.69 | F10: 27597.75 | G10: 2425.88 | H10: =SUM(B10:G10) -> 48583.32
A11: (-) DESPESAS OPERACIONAIS | B11: 0 | C11: 0 | D11: 0 | E11: 6711.68 | F11: 4587.48 | G11: 479.16 | H11: =SUM(B11:G11) -> 11778.32
A12: Folha de Pagamento (Bruto) | B12: 0 | C12: 0 | D12: 0 | E12: 2297.48 | F12: 2064.33 | G12: 193.17 | H12: =SUM(B12:G12) -> 4554.98
A13: NF Rivera Consultoria (Rodney) | B13: 0 | C13: 0 | D13: 0 | E13: 0 | F13: 0 | G13: 0 | H13: =SUM(B13:G13) -> 0
A14: Vale Transporte e Vale Alimentação | B14: 0 | C14: 0 | D14: 0 | E14: 44.28 | F14: 56.78 | G14: 5.41 | H14: =SUM(B14:G14) -> 106.47
A15: FGTS | B15: 0 | C15: 0 | D15: 0 | E15: 172.49 | F15: 158.71 | G15: 14.94 | H15: =SUM(B15:G15) -> 346.14
... A47: (=) RESULTADO LÍQUIDO | B47: 0 | C47: 0 | D47: 0 | E47: 12268.65 | F47: 22606.68 | G47: 1841.2 | H47: =SUM(B47:G47) -> 36716.53
A49: ANÁLISE VERTICAL — % da Receita Líquida (fórmulas)
A50: LINHA | B50: JANEIRO/26 | C50: FEVEREIRO/26 | D50: MARÇO/26 | E50: ABRIL/26 | F50: MAIO/26 | G50: JUNHO/26 | H50: ACUMULADO 1S26
A51: RECEITA LÍQUIDA | B51: =IF(B$4=0,0,B4/B$4) -> 0 | C51: =IF(C$4=0,0,C4/C$4) -> 0 | D51: =IF(D$4=0,0,D4/D$4) -> 0 | E51: =IF(E$4=0,0,E4/E$4) -> 1 | F51: =IF(F$4=0,0,F4/F$4) -> 1 | G51: =IF(G$4=0,0,G4/G$4) -> 1 | H51: =IF(H$4=0,0,H4/H$4) -> 1
A52: MAÇÃ | B52: =IF(B$4=0,0,B5/B$4) -> 0 | C52: =IF(C$4=0,0,C5/C$4) -> 0 | D52: =IF(D$4=0,0,D5/D$4) -> 0 | E52: =IF(E$4=0,0,E5/E$4) -> 1 | F52: =IF(F$4=0,0,F5/F$4) -> 1 | G52: =IF(G$4=0,0,G5/G$4) -> 1 | H52: =IF(H$4=0,0,H5/H$4) -> 1
A53: (-) Devoluções de Vendas | B53: =IF(B$4=0,0,B6/B$4) -> 0 | C53: =IF(C$4=0,0,C6/C$4) -> 0 | D53: =IF(D$4=0,0,D6/D$4) -> 0 | E53: =IF(E$4=0,0,E6/E$4) -> 0 | F53: =IF(F$4=0,0,F6/F$4) -> 0 | G53: =IF(G$4=0,0,G6/G$4) -> 0 | H53: =IF(H$4=0,0,H6/H$4) -> 0
A54: (-) CMV | B54: =IF(B$4=0,0,B7/B$4) -> 0 | C54: =IF(C$4=0,0,C7/C$4) -> 0 | D54: =IF(D$4=0,0,D7/D$4) -> 0 | E54: =IF(E$4=0,0,E7/E$4) -> 0.79888943 | F54: =IF(F$4=0,0,F7/F$4) -> 0.76464882 | G54: =IF(G$4=0,0,G7/G$4) -> 0.76566074 | H54: =IF(H$4=0,0,H7/H$4) -> 0.7790663
A55: (-) CMV MAÇÃ | B55: =IF(B$4=0,0,B8/B$4) -> 0 | C55: =IF(C$4=0,0,C8/C$4) -> 0 | D55: =IF(D$4=0,0,D8/D$4) -> 0 | E55: =IF(E$4=0,0,E8/E$4) -> 0.79888943 | F55: =IF(F$4=0,0,F8/F$4) -> 0.76464882 | G55: =IF(G$4=0,0,G8/G$4) -> 0.76566074 | H55: =IF(H$4=0,0,H8/H$4) -> 0.7790663
A56: Devoluções/Descontos Compras | B56: =IF(B$4=0,0,B9/B$4) -> 0 | C56: =IF(C$4=0,0,C9/C$4) -> 0 | D56: =IF(D$4=0,0,D9/D$4) -> 0 | E56: =IF(E$4=0,0,E9/E$4) -> 0 | F56: =IF(F$4=0,0,F9/F$4) -> 0 | G56: =IF(G$4=0,0,G9/G$4) -> 0 | H56: =IF(H$4=0,0,H9/H$4) -> 0
A57: (=) LUCRO BRUTO | B57: =IF(B$4=0,0,B10/B$4) -> 0 | C57: =IF(C$4=0,0,C10/C$4) -> 0 | D57: =IF(D$4=0,0,D10/D$4) -> 0 | E57: =IF(E$4=0,0,E10/E$4) -> 0.20111057 | F57: =IF(F$4=0,0,F10/F$4) -> 0.23535118 | G57: =IF(G$4=0,0,G10/G$4) -> 0.23433926 | H57: =IF(H$4=0,0,H10/H$4) -> 0.2209337
A58: (-) DESPESAS OPERACIONAIS | B58: =IF(B$4=0,0,B11/B$4) -> 0 | C58: =IF(C$4=0,0,C11/C$4) -> 0 | D58: =IF(D$4=0,0,D11/D$4) -> 0 | E58: =IF(E$4=0,0,E11/E$4) -> 0.072726958 | F58: =IF(F$4=0,0,F11/F$4) -> 0.039121625 | G58: =IF(G$4=0,0,G11/G$4) -> 0.046286708 | H58: =IF(H$4=0,0,H11/H$4) -> 0.053562165
A59: Folha de Pagamento (Bruto) | B59: =IF(B$4=0,0,B12/B$4) -> 0 | C59: =IF(C$4=0,0,C12/C$4) -> 0 | D59: =IF(D$4=0,0,D12/D$4) -> 0 | E59: =IF(E$4=0,0,E12/E$4) -> 0.024895217 | F59: =IF(F$4=0,0,F12/F$4) -> 0.017604424 | G59: =IF(G$4=0,0,G12/G$4) -> 0.018660162 | H59: =IF(H$4=0,0,H12/H$4) -> 0.02071387
A60: NF Rivera Consultoria (Rodney) | B60: =IF(B$4=0,0,B13/B$4) -> 0 | C60: =IF(C$4=0,0,C13/C$4) -> 0 | D60: =IF(D$4=0,0,D13/D$4) -> 0 | E60: =IF(E$4=0,0,E13/E$4) -> 0 | F60: =IF(F$4=0,0,F13/F$4) -> 0 | G60: =IF(G$4=0,0,G13/G$4) -> 0 | H60: =IF(H$4=0,0,H13/H$4) -> 0
A61: Vale Transporte e Vale Alimentação | B61: =IF(B$4=0,0,B14/B$4) -> 0 | C61: =IF(C$4=0,0,C14/C$4) -> 0 | D61: =IF(D$4=0,0,D14/D$4) -> 0 | E61: =IF(E$4=0,0,E14/E$4) -> 0.00047981276 | F61: =IF(F$4=0,0,F14/F$4) -> 0.00048421484 | G61: =IF(G$4=0,0,G14/G$4) -> 0.00052260433 | H61: =IF(H$4=0,0,H14/H$4) -> 0.00048417462
A62: FGTS | B62: =IF(B$4=0,0,B15/B$4) -> 0 | C62: =IF(C$4=0,0,C15/C$4) -> 0 | D62: =IF(D$4=0,0,D15/D$4) -> 0 | E62: =IF(E$4=0,0,E15/E$4) -> 0.0018690809 | F62: =IF(F$4=0,0,F15/F$4) -> 0.0013534649 | G62: =IF(G$4=0,0,G15/G$4) -> 0.0014431994 | H62: =IF(H$4=0,0,H15/H$4) -> 0.0015740791
... A94: (=) RESULTADO LÍQUIDO | B94: =IF(B$4=0,0,B47/B$4) -> 0 | C94: =IF(C$4=0,0,C47/C$4) -> 0 | D94: =IF(D$4=0,0,D47/D$4) -> 0 | E94: =IF(E$4=0,0,E47/E$4) -> 0.13294162 | F94: =IF(F$4=0,0,F47/F$4) -> 0.19278777 | G94: =IF(G$4=0,0,G47/G$4) -> 0.17785935 | H94: =IF(H$4=0,0,H47/H$4) -> 0.16696921

Sheet BETERRABA
A1: DRE GERENCIAL — BETERRABA — Box Ceasa Recife/PE — 1º Semestre 2026
A2: Fonte: "RESULTADO 1S2026 Box RecifePE" (DRE Gerencial, relatório interno Igarashi HF). ACUMULADO e % por fórmula — diferenças de até R$ 0,02 vs. o relatório-fonte são arredondamento dos meses na fonte.
A3: LINHA | B3: JANEIRO/26 | C3: FEVEREIRO/26 | D3: MARÇO/26 | E3: ABRIL/26 | F3: MAIO/26 | G3: JUNHO/26 | H3: ACUMULADO 1S26
A4: RECEITA LÍQUIDA | B4: 28274 | C4: 180 | D4: 0 | E4: 5970 | F4: 20896.44 | G4: 13791.94 | H4: =SUM(B4:G4) -> 69112.38
A5: BETERRABA | B5: 28274 | C5: 180 | D5: 0 | E5: 5970 | F5: 21464 | G5: 14599 | H5: =SUM(B5:G5) -> 70487
A6: (-) Devoluções de Vendas | B6: 0 | C6: 0 | D6: 0 | E6: 0 | F6: -567.56 | G6: -807.06 | H6: =SUM(B6:G6) -> -1374.62
A7: (-) CMV | B7: 29762.29 | C7: 454.88 | D7: 0 | E7: 4918.05 | F7: 24954.14 | G7: 11732.09 | H7: =SUM(B7:G7) -> 71821.45
A8: (-) CMV BETERRABA | B8: 29762.29 | C8: 454.88 | D8: 0 | E8: 4918.05 | F8: 24954.14 | G8: 11732.09 | H8: =SUM(B8:G8) -> 71821.45
A9: (-) Perdas de Mercadorias | B9: 0 | C9: 0 | D9: 0 | E9: 0 | F9: 0 | G9: 0 | H9: =SUM(B9:G9) -> 0
A10: Devoluções/Descontos Compras | B10: 0 | C10: 0 | D10: 0 | E10: 0 | F10: 0 | G10: 0 | H10: =SUM(B10:G10) -> 0
A11: (=) LUCRO BRUTO | B11: -1488.29 | C11: -274.88 | D11: 0 | E11: 1051.95 | F11: -4057.7 | G11: 2059.85 | H11: =SUM(B11:G11) -> -2709.07
A12: (-) DESPESAS OPERACIONAIS | B12: 1936.95 | C12: 13.81 | D12: 0 | E12: 434.18 | F12: 817.5 | G12: 638.38 | H12: =SUM(B12:G12) -> 3840.82
A13: Folha de Pagamento (Bruto) | B13: 277.47 | C13: 4.52 | D13: 0 | E13: 148.62 | F13: 367.87 | G13: 257.35 | H13: =SUM(B13:G13) -> 1055.83
A14: NF Rivera Consultoria (Rodney) | B14: 257.5 | C14: 0 | D14: 0 | E14: 0 | F14: 0 | G14: 0 | H14: =SUM(B14:G14) -> 257.5
A15: Vale Transporte e Vale Alimentação | B15: 16.17 | C15: 0.11 | D15: 0 | E15: 2.86 | F15: 10.12 | G15: 7.21 | H15: =SUM(B15:G15) -> 36.47
... A48: (=) RESULTADO LÍQUIDO | B48: -3438.97 | C48: -287.84 | D48: 0 | E48: 644.98 | F48: -4947.13 | G48: 1280.88 | H48: =SUM(B48:G48) -> -6748.08
A50: ANÁLISE VERTICAL — % da Receita Líquida (fórmulas)
A51: LINHA | B51: JANEIRO/26 | C51: FEVEREIRO/26 | D51: MARÇO/26 | E51: ABRIL/26 | F51: MAIO/26 | G51: JUNHO/26 | H51: ACUMULADO 1S26
A52: RECEITA LÍQUIDA | B52: =IF(B$4=0,0,B4/B$4) -> 1 | C52: =IF(C$4=0,0,C4/C$4) -> 1 | D52: =IF(D$4=0,0,D4/D$4) -> 0 | E52: =IF(E$4=0,0,E4/E$4) -> 1 | F52: =IF(F$4=0,0,F4/F$4) -> 1 | G52: =IF(G$4=0,0,G4/G$4) -> 1 | H52: =IF(H$4=0,0,H4/H$4) -> 1
A53: BETERRABA | B53: =IF(B$4=0,0,B5/B$4) -> 1 | C53: =IF(C$4=0,0,C5/C$4) -> 1 | D53: =IF(D$4=0,0,D5/D$4) -> 0 | E53: =IF(E$4=0,0,E5/E$4) -> 1 | F53: =IF(F$4=0,0,F5/F$4) -> 1.0271606 | G53: =IF(G$4=0,0,G5/G$4) -> 1.0585168 | H53: =IF(H$4=0,0,H5/H$4) -> 1.0198896
A54: (-) Devoluções de Vendas | B54: =IF(B$4=0,0,B6/B$4) -> 0 | C54: =IF(C$4=0,0,C6/C$4) -> 0 | D54: =IF(D$4=0,0,D6/D$4) -> 0 | E54: =IF(E$4=0,0,E6/E$4) -> 0 | F54: =IF(F$4=0,0,F6/F$4) -> -0.027160607 | G54: =IF(G$4=0,0,G6/G$4) -> -0.058516786 | H54: =IF(H$4=0,0,H6/H$4) -> -0.019889635
A55: (-) CMV | B55: =IF(B$4=0,0,B7/B$4) -> 1.0526381 | C55: =IF(C$4=0,0,C7/C$4) -> 2.5271111 | D55: =IF(D$4=0,0,D7/D$4) -> 0 | E55: =IF(E$4=0,0,E7/E$4) -> 0.82379397 | F55: =IF(F$4=0,0,F7/F$4) -> 1.1941814 | G55: =IF(G$4=0,0,G7/G$4) -> 0.85064828 | H55: =IF(H$4=0,0,H7/H$4) -> 1.039198
A56: (-) CMV BETERRABA | B56: =IF(B$4=0,0,B8/B$4) -> 1.0526381 | C56: =IF(C$4=0,0,C8/C$4) -> 2.5271111 | D56: =IF(D$4=0,0,D8/D$4) -> 0 | E56: =IF(E$4=0,0,E8/E$4) -> 0.82379397 | F56: =IF(F$4=0,0,F8/F$4) -> 1.1941814 | G56: =IF(G$4=0,0,G8/G$4) -> 0.85064828 | H56: =IF(H$4=0,0,H8/H$4) -> 1.039198
A57: (-) Perdas de Mercadorias | B57: =IF(B$4=0,0,B9/B$4) -> 0 | C57: =IF(C$4=0,0,C9/C$4) -> 0 | D57: =IF(D$4=0,0,D9/D$4) -> 0 | E57: =IF(E$4=0,0,E9/E$4) -> 0 | F57: =IF(F$4=0,0,F9/F$4) -> 0 | G57: =IF(G$4=0,0,G9/G$4) -> 0 | H57: =IF(H$4=0,0,H9/H$4) -> 0
A58: Devoluções/Descontos Compras | B58: =IF(B$4=0,0,B10/B$4) -> 0 | C58: =IF(C$4=0,0,C10/C$4) -> 0 | D58: =IF(D$4=0,0,D10/D$4) -> 0 | E58: =IF(E$4=0,0,E10/E$4) -> 0 | F58: =IF(F$4=0,0,F10/F$4) -> 0 | G58: =IF(G$4=0,0,G10/G$4) -> 0 | H58: =IF(H$4=0,0,H10/H$4) -> 0
A59: (=) LUCRO BRUTO | B59: =IF(B$4=0,0,B11/B$4) -> -0.052638113 | C59: =IF(C$4=0,0,C11/C$4) -> -1.5271111 | D59: =IF(D$4=0,0,D11/D$4) -> 0 | E59: =IF(E$4=0,0,E11/E$4) -> 0.17620603 | F59: =IF(F$4=0,0,F11/F$4) -> -0.1941814 | G59: =IF(G$4=0,0,G11/G$4) -> 0.14935172 | H59: =IF(H$4=0,0,H11/H$4) -> -0.039198042
A60: (-) DESPESAS OPERACIONAIS | B60: =IF(B$4=0,0,B12/B$4) -> 0.068506402 | C60: =IF(C$4=0,0,C12/C$4) -> 0.076722222 | D60: =IF(D$4=0,0,D12/D$4) -> 0 | E60: =IF(E$4=0,0,E12/E$4) -> 0.072726968 | F60: =IF(F$4=0,0,F12/F$4) -> 0.039121496 | G60: =IF(G$4=0,0,G12/G$4) -> 0.046286454 | H60: =IF(H$4=0,0,H12/H$4) -> 0.055573546
A61: Folha de Pagamento (Bruto) | B61: =IF(B$4=0,0,B13/B$4) -> 0.0098136097 | C61: =IF(C$4=0,0,C13/C$4) -> 0.025111111 | D61: =IF(D$4=0,0,D13/D$4) -> 0 | E61: =IF(E$4=0,0,E13/E$4) -> 0.024894472 | F61: =IF(F$4=0,0,F13/F$4) -> 0.017604434 | G61: =IF(G$4=0,0,G13/G$4) -> 0.018659449 | H61: =IF(H$4=0,0,H13/H$4) -> 0.015277002
A62: NF Rivera Consultoria (Rodney) | B62: =IF(B$4=0,0,B14/B$4) -> 0.0091073071 | C62: =IF(C$4=0,0,C14/C$4) -> 0 | D62: =IF(D$4=0,0,D14/D$4) -> 0 | E62: =IF(E$4=0,0,E14/E$4) -> 0 | F62: =IF(F$4=0,0,F14/F$4) -> 0 | G62: =IF(G$4=0,0,G14/G$4) -> 0 | H62: =IF(H$4=0,0,H14/H$4) -> 0.0037258158
A63: Vale Transporte e Vale Alimentação | B63: =IF(B$4=0,0,B15/B$4) -> 0.00057190352 | C63: =IF(C$4=0,0,C15/C$4) -> 0.00061111111 | D63: =IF(D$4=0,0,D15/D$4) -> 0 | E63: =IF(E$4=0,0,E15/E$4) -> 0.00047906198 | F63: =IF(F$4=0,0,F15/F$4) -> 0.00048429302 | G63: =IF(G$4=0,0,G15/G$4) -> 0.0005227691 | H63: =IF(H$4=0,0,H15/H$4) -> 0.00052769128
... A96: (=) RESULTADO LÍQUIDO | B96: =IF(B$4=0,0,B48/B$4) -> -0.12163012 | C96: =IF(C$4=0,0,C48/C$4) -> -1.5991111 | D96: =IF(D$4=0,0,D48/D$4) -> 0 | E96: =IF(E$4=0,0,E48/E$4) -> 0.10803685 | F96: =IF(F$4=0,0,F48/F$4) -> -0.23674511 | G96: =IF(G$4=0,0,G48/G$4) -> 0.092871634 | H96: =IF(H$4=0,0,H48/H$4) -> -0.097639236

Sheet MIRTILO
A1: DRE GERENCIAL — MIRTILO — Box Ceasa Recife/PE — 1º Semestre 2026
A2: Fonte: "RESULTADO 1S2026 Box RecifePE" (DRE Gerencial, relatório interno Igarashi HF). ACUMULADO e % por fórmula — diferenças de até R$ 0,02 vs. o relatório-fonte são arredondamento dos meses na fonte.
A3: LINHA | B3: JANEIRO/26 | C3: FEVEREIRO/26 | D3: MARÇO/26 | E3: ABRIL/26 | F3: MAIO/26 | G3: JUNHO/26 | H3: ACUMULADO 1S26
A4: RECEITA LÍQUIDA | B4: 9504 | C4: 0 | D4: 10253 | E4: 1008 | F4: 144 | G4: 0 | H4: =SUM(B4:G4) -> 20909
A5: MIRTILO | B5: 9504 | C5: 0 | D5: 10253 | E5: 1008 | F5: 144 | G5: 0 | H5: =SUM(B5:G5) -> 20909
A6: (-) Devoluções de Vendas | B6: 0 | C6: 0 | D6: 0 | E6: 0 | F6: 0 | G6: 0 | H6: =SUM(B6:G6) -> 0
A7: (-) CMV | B7: 7603.2 | C7: 0 | D7: 8123.2 | E7: 696.73 | F7: 527.39 | G7: 0 | H7: =SUM(B7:G7) -> 16950.52
A8: (-) CMV MIRTILO | B8: 7603.2 | C8: 0 | D8: 8123.2 | E8: 696.73 | F8: 116.12 | G8: 0 | H8: =SUM(B8:G8) -> 16539.25
A9: (-) Perdas de Mercadorias | B9: 0 | C9: 0 | D9: 0 | E9: 0 | F9: 411.27 | G9: 0 | H9: =SUM(B9:G9) -> 411.27
A10: Devoluções/Descontos Compras | B10: 0 | C10: 0 | D10: 0 | E10: 0 | F10: 0 | G10: 0 | H10: =SUM(B10:G10) -> 0
A11: (=) LUCRO BRUTO | B11: 1900.8 | C11: 0 | D11: 2129.8 | E11: 311.27 | F11: -383.39 | G11: 0 | H11: =SUM(B11:G11) -> 3958.48
A12: (-) DESPESAS OPERACIONAIS | B12: 651.08 | C12: 0 | D12: 595.22 | E12: 73.31 | F12: 5.63 | G12: 0 | H12: =SUM(B12:G12) -> 1325.24
A13: Folha de Pagamento (Bruto) | B13: 93.27 | C13: 0 | D13: 183.94 | E13: 25.09 | F13: 2.54 | G13: 0 | H13: =SUM(B13:G13) -> 304.84
A14: NF Rivera Consultoria (Rodney) | B14: 86.56 | C14: 0 | D14: 0 | E14: 0 | F14: 0 | G14: 0 | H14: =SUM(B14:G14) -> 86.56
A15: Vale Transporte e Vale Alimentação | B15: 5.43 | C15: 0 | D15: 3.3 | E15: 0.48 | F15: 0.07 | G15: 0 | H15: =SUM(B15:G15) -> 9.28
... A48: (=) RESULTADO LÍQUIDO | B48: 1245.1 | C48: 0 | D48: 1558.08 | E48: 242.55 | F48: -389.52 | G48: 0 | H48: =SUM(B48:G48) -> 2656.21
A50: ANÁLISE VERTICAL — % da Receita Líquida (fórmulas)
A51: LINHA | B51: JANEIRO/26 | C51: FEVEREIRO/26 | D51: MARÇO/26 | E51: ABRIL/26 | F51: MAIO/26 | G51: JUNHO/26 | H51: ACUMULADO 1S26
A52: RECEITA LÍQUIDA | B52: =IF(B$4=0,0,B4/B$4) -> 1 | C52: =IF(C$4=0,0,C4/C$4) -> 0 | D52: =IF(D$4=0,0,D4/D$4) -> 1 | E52: =IF(E$4=0,0,E4/E$4) -> 1 | F52: =IF(F$4=0,0,F4/F$4) -> 1 | G52: =IF(G$4=0,0,G4/G$4) -> 0 | H52: =IF(H$4=0,0,H4/H$4) -> 1
A53: MIRTILO | B53: =IF(B$4=0,0,B5/B$4) -> 1 | C53: =IF(C$4=0,0,C5/C$4) -> 0 | D53: =IF(D$4=0,0,D5/D$4) -> 1 | E53: =IF(E$4=0,0,E5/E$4) -> 1 | F53: =IF(F$4=0,0,F5/F$4) -> 1 | G53: =IF(G$4=0,0,G5/G$4) -> 0 | H53: =IF(H$4=0,0,H5/H$4) -> 1
A54: (-) Devoluções de Vendas | B54: =IF(B$4=0,0,B6/B$4) -> 0 | C54: =IF(C$4=0,0,C6/C$4) -> 0 | D54: =IF(D$4=0,0,D6/D$4) -> 0 | E54: =IF(E$4=0,0,E6/E$4) -> 0 | F54: =IF(F$4=0,0,F6/F$4) -> 0 | G54: =IF(G$4=0,0,G6/G$4) -> 0 | H54: =IF(H$4=0,0,H6/H$4) -> 0
A55: (-) CMV | B55: =IF(B$4=0,0,B7/B$4) -> 0.8 | C55: =IF(C$4=0,0,C7/C$4) -> 0 | D55: =IF(D$4=0,0,D7/D$4) -> 0.79227543 | E55: =IF(E$4=0,0,E7/E$4) -> 0.6912004 | F55: =IF(F$4=0,0,F7/F$4) -> 3.6624306 | G55: =IF(G$4=0,0,G7/G$4) -> 0 | H55: =IF(H$4=0,0,H7/H$4) -> 0.81068057
A56: (-) CMV MIRTILO | B56: =IF(B$4=0,0,B8/B$4) -> 0.8 | C56: =IF(C$4=0,0,C8/C$4) -> 0 | D56: =IF(D$4=0,0,D8/D$4) -> 0.79227543 | E56: =IF(E$4=0,0,E8/E$4) -> 0.6912004 | F56: =IF(F$4=0,0,F8/F$4) -> 0.80638889 | G56: =IF(G$4=0,0,G8/G$4) -> 0 | H56: =IF(H$4=0,0,H8/H$4) -> 0.79101105
A57: (-) Perdas de Mercadorias | B57: =IF(B$4=0,0,B9/B$4) -> 0 | C57: =IF(C$4=0,0,C9/C$4) -> 0 | D57: =IF(D$4=0,0,D9/D$4) -> 0 | E57: =IF(E$4=0,0,E9/E$4) -> 0 | F57: =IF(F$4=0,0,F9/F$4) -> 2.8560417 | G57: =IF(G$4=0,0,G9/G$4) -> 0 | H57: =IF(H$4=0,0,H9/H$4) -> 0.01966952
A58: Devoluções/Descontos Compras | B58: =IF(B$4=0,0,B10/B$4) -> 0 | C58: =IF(C$4=0,0,C10/C$4) -> 0 | D58: =IF(D$4=0,0,D10/D$4) -> 0 | E58: =IF(E$4=0,0,E10/E$4) -> 0 | F58: =IF(F$4=0,0,F10/F$4) -> 0 | G58: =IF(G$4=0,0,G10/G$4) -> 0 | H58: =IF(H$4=0,0,H10/H$4) -> 0
A59: (=) LUCRO BRUTO | B59: =IF(B$4=0,0,B11/B$4) -> 0.2 | C59: =IF(C$4=0,0,C11/C$4) -> 0 | D59: =IF(D$4=0,0,D11/D$4) -> 0.20772457 | E59: =IF(E$4=0,0,E11/E$4) -> 0.3087996 | F59: =IF(F$4=0,0,F11/F$4) -> -2.6624306 | G59: =IF(G$4=0,0,G11/G$4) -> 0 | H59: =IF(H$4=0,0,H11/H$4) -> 0.18931943
A60: (-) DESPESAS OPERACIONAIS | B60: =IF(B$4=0,0,B12/B$4) -> 0.068505892 | C60: =IF(C$4=0,0,C12/C$4) -> 0 | D60: =IF(D$4=0,0,D12/D$4) -> 0.058053253 | E60: =IF(E$4=0,0,E12/E$4) -> 0.072728175 | F60: =IF(F$4=0,0,F12/F$4) -> 0.039097222 | G60: =IF(G$4=0,0,G12/G$4) -> 0 | H60: =IF(H$4=0,0,H12/H$4) -> 0.063381319
